Workbook

Sheet Dashboard
A1: Supply Chain Tracker — Dashboard
A2: All figures below are calculated live from the Purchase Orders and Inventory & Coverage sheets.
A4: Key Metrics
A5: Total Open POs | B5: =COUNTA('Purchase Orders'!A6:A11) -> 6 | D5: Total SKUs Tracked | E5: =COUNTA('Inventory & Coverage'!A8:A16) -> 9
A6: POs — High Risk | B6: =COUNTIF('Purchase Orders'!O6:O11,"High Risk") -> 2 | D6: SKUs — High Stockout Risk (Total) | E6: =COUNTIF('Inventory & Coverage'!K8:K16,"High Risk") -> 0
A7: POs — Medium Risk | B7: =COUNTIF('Purchase Orders'!O6:O11,"Medium Risk") -> 1 | D7: SKUs — Medium Stockout Risk (Total) | E7: =COUNTIF('Inventory & Coverage'!K8:K16,"Medium Risk") -> 9
A8: POs — Low Risk | B8: =COUNTIF('Purchase Orders'!O6:O11,"Low Risk") -> 3 | D8: SKUs — High Stockout Risk (UK) | E8: =COUNTIF('Inventory & Coverage'!M8:M16,"High Risk") -> 9
A9: Total Units on Order | B9: =SUM('Purchase Orders'!F6:F11) -> 3000 | D9: Total On-Hand Inventory (All Whses) | E9: =SUM('Inventory & Coverage'!H8:H16) -> 1966
A10: Open POs Shipping to UK | B10: =COUNTIF('Purchase Orders'!H6:H11,"UK") -> 0 | D10: Total UK On-Hand Inventory | E10: =SUM('Inventory & Coverage'!F8:F16) -> 221
A11: Any Open PO Shipping to UK? | B11: =IF(B10>0,"Yes","No") -> No | D11: UK High-Risk SKUs w/ Zero Incoming UK PO | E11: =SUMPRODUCT(('Inventory & Coverage'!M8:M16="High Risk")*('Inventory & Coverage'!O8:O16=0)) -> 9
A13: PO Risk Breakdown | D13: SKU Stockout Risk Breakdown
A14: Risk Level | B14: Count | D14: Risk Level | E14: Total Basis | F14: UK Basis
A15: High Risk | B15: =COUNTIF('Purchase Orders'!O6:O11,"High Risk") -> 2 | D15: High Risk | E15: =COUNTIF('Inventory & Coverage'!K8:K16,"High Risk") -> 0 | F15: =COUNTIF('Inventory & Coverage'!M8:M16,"High Risk") -> 9
A16: Medium Risk | B16: =COUNTIF('Purchase Orders'!O6:O11,"Medium Risk") -> 1 | D16: Medium Risk | E16: =COUNTIF('Inventory & Coverage'!K8:K16,"Medium Risk") -> 9 | F16: =COUNTIF('Inventory & Coverage'!M8:M16,"Medium Risk") -> 0
A17: Low Risk | B17: =COUNTIF('Purchase Orders'!O6:O11,"Low Risk") -> 3 | D17: Low Risk | E17: =COUNTIF('Inventory & Coverage'!K8:K16,"Low Risk") -> 0 | F17: =COUNTIF('Inventory & Coverage'!M8:M16,"Low Risk") -> 0
A18: Review | B18: =COUNTIF('Purchase Orders'!O6:O11,"Review") -> 0
A20: Key Alerts
A21: ="UK Warehouse Shipping: "&IF(B10=0,"No open purchase orders are currently shipping to the UK warehouse.",B10&" open PO(s) shipping to UK.") -> UK Warehouse Shipping: No open purchase orders are currently shipping to the UK warehouse.
A22: ="UK Stockout Risk: "&E8&" of "&E5&" SKUs are at High stockout risk in the UK warehouse; "&E11&" of those currently have zero replenishment in transit to UK." -> UK Stockout Risk: 9 of 9 SKUs are at High stockout risk in the UK warehouse; 9 of those currently have zero replenishment in transit to UK.
A23: ="Purchase Order Risk: "&B6&" of "&B5&" open PO(s) are flagged High Risk and require follow-up." -> Purchase Order Risk: 2 of 6 open PO(s) are flagged High Risk and require follow-up.

Sheet Purchase Orders
A1: Purchase Orders
A3: Blue text = source input data entered from PO records. Black text = formulas (do not overwrite).
A5: PO # | B5: Factory | C5: Factory City | D5: SKU | E5: Product | F5: Qty | G5: Status | H5: Destination Warehouse | I5: Ship Method | J5: Stated ETA Notes | K5: Stated ETA (Weeks) | L5: Ref. Sea Transit (Wks) | M5: Ref. Air Transit (Wks) | N5: Applicable Ref. Transit (Wks) | O5: PO Risk Flag | P5: Ships to UK Warehouse?
A6: PO-410 | B6: Factory A | C6: =IFERROR(INDEX('Reference Data'!$B$22:$B$27,MATCH(B6,'Reference Data'!$A$22:$A$27,0)),"N/A") -> Shenzhen | D6: HN-RB-300 | E6: =IFERROR(INDEX('Reference Data'!$B$10:$B$18,MATCH(D6,'Reference Data'!$A$10:$A$18,0)),"N/A") -> Recovery Balm 300ml | F6: 500 | G6: In production — on track | H6: HK | I6: Sea | J6: Ships to HK, ETA 3.5 weeks | K6: 3.5 | L6: =IFERROR(INDEX('Reference Data'!$C$31:$C$45,MATCH($C6&"|"&$H6,'Reference Data'!$F$31:$F$45,0)),"N/A") -> 0.28571429 | M6: =IFERROR(INDEX('Reference Data'!$E$31:$E$45,MATCH($C6&"|"&$H6,'Reference Data'!$F$31:$F$45,0)),"N/A") -> 0.14285714 | N6: =IF(I6="Air",M6,IF(I6="Sea",L6,"N/A")) -> 0.28571429 | O6: =IF(ISNUMBER(SEARCH("delayed",G6)),"High Risk",IF(ISNUMBER(SEARCH("Unconfirmed",G6)),"High Risk",IF(ISNUMBER(SEARCH("Completed",G6)),"Medium Risk",IF(ISNUMBER(SEARCH("on track",G6)),"Low Risk","Review")))) -> Low Risk | P6: =IF(H6="UK","Yes","No") -> No
A7: PO-411 | B7: Factory A | C7: =IFERROR(INDEX('Reference Data'!$B$22:$B$27,MATCH(B7,'Reference Data'!$A$22:$A$27,0)),"N/A") -> Shenzhen | D7: HN-NC-075 | E7: =IFERROR(INDEX('Reference Data'!$B$10:$B$18,MATCH(D7,'Reference Data'!$A$10:$A$18,0)),"N/A") -> Night Cream 75ml | F7: 500 | G7: In production — on track | H7: US | I7: Sea | J7: Ships to LA, ETA 4 weeks | K7: 4 | L7: =IFERROR(INDEX('Reference Data'!$C$31:$C$45,MATCH($C7&"|"&$H7,'Reference Data'!$F$31:$F$45,0)),"N/A") -> 3 | M7: =IFERROR(INDEX('Reference Data'!$E$31:$E$45,MATCH($C7&"|"&$H7,'Reference Data'!$F$31:$F$45,0)),"N/A") -> 0.71428571 | N7: =IF(I7="Air",M7,IF(I7="Sea",L7,"N/A")) -> 3 | O7: =IF(ISNUMBER(SEARCH("delayed",G7)),"High Risk",IF(ISNUMBER(SEARCH("Unconfirmed",G7)),"High Risk",IF(ISNUMBER(SEARCH("Completed",G7)),"Medium Risk",IF(ISNUMBER(SEARCH("on track",G7)),"Low Risk","Review")))) -> Low Risk | P7: =IF(H7="UK","Yes","No") -> No
A8: PO-412 | B8: Factory C | C8: =IFERROR(INDEX('Reference Data'!$B$22:$B$27,MATCH(B8,'Reference Data'!$A$22:$A$27,0)),"N/A") -> Jakarta | D8: HN-HM-100 | E8: =IFERROR(INDEX('Reference Data'!$B$10:$B$18,MATCH(D8,'Reference Data'!$A$10:$A$18,0)),"N/A") -> Hair Mask 100ml | F8: 300 | G8: Production delayed — raw material shortage | H8: Unknown | I8: Unknown | J8: Originally ETA 3 weeks, now unknown | K8: Unknown | L8: =IFERROR(INDEX('Reference Data'!$C$31:$C$45,MATCH($C8&"|"&$H8,'Reference Data'!$F$31:$F$45,0)),"N/A") -> N/A | M8: =IFERROR(INDEX('Reference Data'!$E$31:$E$45,MATCH($C8&"|"&$H8,'Reference Data'!$F$31:$F$45,0)),"N/A") -> N/A | N8: =IF(I8="Air",M8,IF(I8="Sea",L8,"N/A")) -> N/A | O8: =IF(ISNUMBER(SEARCH("delayed",G8)),"High Risk",IF(ISNUMBER(SEARCH("Unconfirmed",G8)),"High Risk",IF(ISNUMBER(SEARCH("Completed",G8)),"Medium Risk",IF(ISNUMBER(SEARCH("on track",G8)),"Low Risk","Review")))) -> High Risk | P8: =IF(H8="UK","Yes","No") -> No
A9: PO-413 | B9: Factory D | C9: =IFERROR(INDEX('Reference Data'!$B$22:$B$27,MATCH(B9,'Reference Data'!$A$22:$A$27,0)),"N/A") -> Taipei | D9: HN-LB-250 | E9: =IFERROR(INDEX('Reference Data'!$B$10:$B$18,MATCH(D9,'Reference Data'!$A$10:$A$18,0)),"N/A") -> Lip Balm 3-Pack | F9: 1000 | G9: Completed — ready for pickup | H9: Unknown | I9: Unknown | J9: Awaiting shipping instructions | K9: Unknown | L9: =IFERROR(INDEX('Reference Data'!$C$31:$C$45,MATCH($C9&"|"&$H9,'Reference Data'!$F$31:$F$45,0)),"N/A") -> N/A | M9: =IFERROR(INDEX('Reference Data'!$E$31:$E$45,MATCH($C9&"|"&$H9,'Reference Data'!$F$31:$F$45,0)),"N/A") -> N/A | N9: =IF(I9="Air",M9,IF(I9="Sea",L9,"N/A")) -> N/A | O9: =IF(ISNUMBER(SEARCH("delayed",G9)),"High Risk",IF(ISNUMBER(SEARCH("Unconfirmed",G9)),"High Risk",IF(ISNUMBER(SEARCH("Completed",G9)),"Medium Risk",IF(ISNUMBER(SEARCH("on track",G9)),"Low Risk","Review")))) -> Medium Risk | P9: =IF(H9="UK","Yes","No") -> No
A10: PO-414 | B10: Factory E | C10: =IFERROR(INDEX('Reference Data'!$B$22:$B$27,MATCH(B10,'Reference Data'!$A$22:$A$27,0)),"N/A") -> Chiang Mai | D10: HN-EO-030 | E10: =IFERROR(INDEX('Reference Data'!$B$10:$B$18,MATCH(D10,'Reference Data'!$A$10:$A$18,0)),"N/A") -> Essential Oil Blend 30ml | F10: 200 | G10: Unconfirmed — awaiting factory response (4 days) | H10: Unknown | I10: Unknown | J10: Unknown | K10: Unknown | L10: =IFERROR(INDEX('Reference Data'!$C$31:$C$45,MATCH($C10&"|"&$H10,'Reference Data'!$F$31:$F$45,0)),"N/A") -> N/A | M10: =IFERROR(INDEX('Reference Data'!$E$31:$E$45,MATCH($C10&"|"&$H10,'Reference Data'!$F$31:$F$45,0)),"N/A") -> N/A | N10: =IF(I10="Air",M10,IF(I10="Sea",L10,"N/A")) -> N/A | O10: =IF(ISNUMBER(SEARCH("delayed",G10)),"High Risk",IF(ISNUMBER(SEARCH("Unconfirmed",G10)),"High Risk",IF(ISNUMBER(SEARCH("Completed",G10)),"Medium Risk",IF(ISNUMBER(SEARCH("on track",G10)),"Low Risk","Review")))) -> High Risk | P10: =IF(H10="UK","Yes","No") -> No
A11: PO-415 | B11: Factory F | C11: =IFERROR(INDEX('Reference Data'!$B$22:$B$27,MATCH(B11,'Reference Data'!$A$22:$A$27,0)),"N/A") -> Ho Chi Minh City | D11: HN-BC-400 | E11: =IFERROR(INDEX('Reference Data'!$B$10:$B$18,MATCH(D11,'Reference Data'!$A$10:$A$18,0)),"N/A") -> Bath Crystals 400g | F11: 500 | G11: In production — on track | H11: US | I11: Sea | J11: Ships to LA, ETA 6 weeks (sea) | K11: 6 | L11: =IFERROR(INDEX('Reference Data'!$C$31:$C$45,MATCH($C11&"|"&$H11,'Reference Data'!$F$31:$F$45,0)),"N/A") -> 3.5 | M11: =IFERROR(INDEX('Reference Data'!$E$31:$E$45,MATCH($C11&"|"&$H11,'Reference Data'!$F$31:$F$45,0)),"N/A") -> 0.71428571 | N11: =IF(I11="Air",M11,IF(I11="Sea",L11,"N/A")) -> 3.5 | O11: =IF(ISNUMBER(SEARCH("delayed",G11)),"High Risk",IF(ISNUMBER(SEARCH("Unconfirmed",G11)),"High Risk",IF(ISNUMBER(SEARCH("Completed",G11)),"Medium Risk",IF(ISNUMBER(SEARCH("on track",G11)),"Low Risk","Review")))) -> Low Risk | P11: =IF(H11="UK","Yes","No") -> No
A12: TOTAL | F12: =SUM(F6:F11) -> 3000
A14: Notes & Assumptions
A15: • Destination Warehouse and Ship Method are extracted from each PO's status/ETA notes as provided; recorded as 'Unknown' where the source did not specify a destination or method yet.
A16: • Ship Method is assumed 'Sea' where not explicitly stated but the ETA is multi-week in scale (consistent with sea freight lead times in Reference Data); PO-415 explicitly stated '(sea)'.
A17: • PO Risk Flag is a formula that searches the Status text for keywords ("delayed", "Unconfirmed", "Completed", "on track") — edit the Status text and the flag recalculates automatically.
A18: • Reference Sea/Air Transit columns are pulled live from the Reference Data Shipping Lead Times table via the Factory City + Destination Warehouse route — they show the typical transit time for that lane, for comparison against the Stated ETA.

Sheet Inventory & Coverage
A1: Inventory & Coverage
A3: Stockout Risk Thresholds (editable assumptions):
A4: High Risk if Weeks of Cover < | B4: 4
A5: Medium Risk if Weeks of Cover < | B5: 8 | C5: (Low Risk otherwise)
A7: SKU | B7: Product | C7: Category | D7: Primary Factory | E7: US (LA) Qty | F7: UK (Manchester) Qty | G7: HK Qty | H7: Total Qty | I7: Weekly Sell- Through Rate | J7: Total Weeks of Cover | K7: Total Stockout Risk | L7: UK Weeks of Cover | M7: UK Stockout Risk | N7: Open PO Qty (All Dest.) | O7: Open PO Qty to UK
A8: HN-RB-300 | B8: =IFERROR(INDEX('Reference Data'!$B$10:$B$18,MATCH($A8,'Reference Data'!$A$10:$A$18,0)),"N/A") -> Recovery Balm 300ml | C8: =IFERROR(INDEX('Reference Data'!$C$10:$C$18,MATCH($A8,'Reference Data'!$A$10:$A$18,0)),"N/A") -> Body Care | D8: =IFERROR(INDEX('Reference Data'!$D$10:$D$18,MATCH($A8,'Reference Data'!$A$10:$A$18,0)),"N/A") -> Factory A | E8: 220 | F8: 35 | G8: 110 | H8: =SUM(E8:G8) -> 365 | I8: 75 | J8: =IFERROR(H8/I8,"N/A") -> 4.8666667 | K8: =IF(J8<$B$4,"High Risk",IF(J8<$B$5,"Medium Risk","Low Risk")) -> Medium Risk | L8: =IFERROR(F8/I8,"N/A") -> 0.46666667 | M8: =IF(L8<$B$4,"High Risk",IF(L8<$B$5,"Medium Risk","Low Risk")) -> High Risk | N8: =SUMIF('Purchase Orders'!$D$6:$D$11,$A8,'Purchase Orders'!$F$6:$F$11) -> 500 | O8: =SUMIFS('Purchase Orders'!$F$6:$F$11,'Purchase Orders'!$D$6:$D$11,$A8,'Purchase Orders'!$H$6:$H$11,"UK") -> 0
A9: HN-FS-050 | B9: =IFERROR(INDEX('Reference Data'!$B$10:$B$18,MATCH($A9,'Reference Data'!$A$10:$A$18,0)),"N/A") -> Face Serum 50ml | C9: =IFERROR(INDEX('Reference Data'!$C$10:$C$18,MATCH($A9,'Reference Data'!$A$10:$A$18,0)),"N/A") -> Skincare | D9: =IFERROR(INDEX('Reference Data'!$D$10:$D$18,MATCH($A9,'Reference Data'!$A$10:$A$18,0)),"N/A") -> Factory A | E9: 150 | F9: 20 | G9: 75 | H9: =SUM(E9:G9) -> 245 | I9: 45 | J9: =IFERROR(H9/I9,"N/A") -> 5.4444444 | K9: =IF(J9<$B$4,"High Risk",IF(J9<$B$5,"Medium Risk","Low Risk")) -> Medium Risk | L9: =IFERROR(F9/I9,"N/A") -> 0.44444444 | M9: =IF(L9<$B$4,"High Risk",IF(L9<$B$5,"Medium Risk","Low Risk")) -> High Risk | N9: =SUMIF('Purchase Orders'!$D$6:$D$11,$A9,'Purchase Orders'!$F$6:$F$11) -> 0 | O9: =SUMIFS('Purchase Orders'!$F$6:$F$11,'Purchase Orders'!$D$6:$D$11,$A9,'Purchase Orders'!$H$6:$H$11,"UK") -> 0
A10: HN-BW-200 | B10: =IFERROR(INDEX('Reference Data'!$B$10:$B$18,MATCH($A10,'Reference Data'!$A$10:$A$18,0)),"N/A") -> Body Wash 200ml | C10: =IFERROR(INDEX('Reference Data'!$C$10:$C$18,MATCH($A10,'Reference Data'!$A$10:$A$18,0)),"N/A") -> Body Care | D10: =IFERROR(INDEX('Reference Data'!$D$10:$D$18,MATCH($A10,'Reference Data'!$A$10:$A$18,0)),"N/A") -> Factory B | E10: 180 | F10: 50 | G10: 60 | H10: =SUM(E10:G10) -> 290 | I10: 55 | J10: =IFERROR(H10/I10,"N/A") -> 5.2727273 | K10: =IF(J10<$B$4,"High Risk",IF(J10<$B$5,"Medium Risk","Low Risk")) -> Medium Risk | L10: =IFERROR(F10/I10,"N/A") -> 0.90909091 | M10: =IF(L10<$B$4,"High Risk",IF(L10<$B$5,"Medium Risk","Low Risk")) -> High Risk | N10: =SUMIF('Purchase Orders'!$D$6:$D$11,$A10,'Purchase Orders'!$F$6:$F$11) -> 0 | O10: =SUMIFS('Purchase Orders'!$F$6:$F$11,'Purchase Orders'!$D$6:$D$11,$A10,'Purchase Orders'!$H$6:$H$11,"UK") -> 0
A11: HN-HM-100 | B11: =IFERROR(INDEX('Reference Data'!$B$10:$B$18,MATCH($A11,'Reference Data'!$A$10:$A$18,0)),"N/A") -> Hair Mask 100ml | C11: =IFERROR(INDEX('Reference Data'!$C$10:$C$18,MATCH($A11,'Reference Data'!$A$10:$A$18,0)),"N/A") -> Hair Care | D11: =IFERROR(INDEX('Reference Data'!$D$10:$D$18,MATCH($A11,'Reference Data'!$A$10:$A$18,0)),"N/A") -> Factory C | E11: 90 | F11: 25 | G11: 45 | H11: =SUM(E11:G11) -> 160 | I11: 30 | J11: =IFERROR(H11/I11,"N/A") -> 5.3333333 | K11: =IF(J11<$B$4,"High Risk",IF(J11<$B$5,"Medium Risk","Low Risk")) -> Medium Risk | L11: =IFERROR(F11/I11,"N/A") -> 0.83333333 | M11: =IF(L11<$B$4,"High Risk",IF(L11<$B$5,"Medium Risk","Low Risk")) -> High Risk | N11: =SUMIF('Purchase Orders'!$D$6:$D$11,$A11,'Purchase Orders'!$F$6:$F$11) -> 300 | O11: =SUMIFS('Purchase Orders'!$F$6:$F$11,'Purchase Orders'!$D$6:$D$11,$A11,'Purchase Orders'!$H$6:$H$11,"UK") -> 0
A12: HN-LB-250 | B12: =IFERROR(INDEX('Reference Data'!$B$10:$B$18,MATCH($A12,'Reference Data'!$A$10:$A$18,0)),"N/A") -> Lip Balm 3-Pack | C12: =IFERROR(INDEX('Reference Data'!$C$10:$C$18,MATCH($A12,'Reference Data'!$A$10:$A$18,0)),"N/A") -> Skincare | D12: =IFERROR(INDEX('Reference Data'!$D$10:$D$18,MATCH($A12,'Reference Data'!$A$10:$A$18,0)),"N/A") -> Factory D | E12: 300 | F12: 40 | G12: 80 | H12: =SUM(E12:G12) -> 420 | I12: 60 | J12: =IFERROR(H12/I12,"N/A") -> 7 | K12: =IF(J12<$B$4,"High Risk",IF(J12<$B$5,"Medium Risk","Low Risk")) -> Medium Risk | L12: =IFERROR(F12/I12,"N/A") -> 0.66666667 | M12: =IF(L12<$B$4,"High Risk",IF(L12<$B$5,"Medium Risk","Low Risk")) -> High Risk | N12: =SUMIF('Purchase Orders'!$D$6:$D$11,$A12,'Purchase Orders'!$F$6:$F$11) -> 1000 | O12: =SUMIFS('Purchase Orders'!$F$6:$F$11,'Purchase Orders'!$D$6:$D$11,$A12,'Purchase Orders'!$H$6:$H$11,"UK") -> 0
A13: HN-SM-150 | B13: =IFERROR(INDEX('Reference Data'!$B$10:$B$18,MATCH($A13,'Reference Data'!$A$10:$A$18,0)),"N/A") -> Scalp Mist 150ml | C13: =IFERROR(INDEX('Reference Data'!$C$10:$C$18,MATCH($A13,'Reference Data'!$A$10:$A$18,0)),"N/A") -> Hair Care | D13: =IFERROR(INDEX('Reference Data'!$D$10:$D$18,MATCH($A13,'Reference Data'!$A$10:$A$18,0)),"N/A") -> Factory C | E13: 70 | F13: 10 | G13: 30 | H13: =SUM(E13:G13) -> 110 | I13: 20 | J13: =IFERROR(H13/I13,"N/A") -> 5.5 | K13: =IF(J13<$B$4,"High Risk",IF(J13<$B$5,"Medium Risk","Low Risk")) -> Medium Risk | L13: =IFERROR(F13/I13,"N/A") -> 0.5 | M13: =IF(L13<$B$4,"High Risk",IF(L13<$B$5,"Medium Risk","Low Risk")) -> High Risk | N13: =SUMIF('Purchase Orders'!$D$6:$D$11,$A13,'Purchase Orders'!$F$6:$F$11) -> 0 | O13: =SUMIFS('Purchase Orders'!$F$6:$F$11,'Purchase Orders'!$D$6:$D$11,$A13,'Purchase Orders'!$H$6:$H$11,"UK") -> 0
A14: HN-EO-030 | B14: =IFERROR(INDEX('Reference Data'!$B$10:$B$18,MATCH($A14,'Reference Data'!$A$10:$A$18,0)),"N/A") -> Essential Oil Blend 30ml | C14: =IFERROR(INDEX('Reference Data'!$C$10:$C$18,MATCH($A14,'Reference Data'!$A$10:$A$18,0)),"N/A") -> Wellness | D14: =IFERROR(INDEX('Reference Data'!$D$10:$D$18,MATCH($A14,'Reference Data'!$A$10:$A$18,0)),"N/A") -> Factory E | E14: 45 | F14: 8 | G14: 20 | H14: =SUM(E14:G14) -> 73 | I14: 15 | J14: =IFERROR(H14/I14,"N/A") -> 4.8666667 | K14: =IF(J14<$B$4,"High Risk",IF(J14<$B$5,"Medium Risk","Low Risk")) -> Medium Risk | L14: =IFERROR(F14/I14,"N/A") -> 0.53333333 | M14: =IF(L14<$B$4,"High Risk",IF(L14<$B$5,"Medium Risk","Low Risk")) -> High Risk | N14: =SUMIF('Purchase Orders'!$D$6:$D$11,$A14,'Purchase Orders'!$F$6:$F$11) -> 200 | O14: =SUMIFS('Purchase Orders'!$F$6:$F$11,'Purchase Orders'!$D$6:$D$11,$A14,'Purchase Orders'!$H$6:$H$11,"UK") -> 0
A15: HN-BC-400 | B15: =IFERROR(INDEX('Reference Data'!$B$10:$B$18,MATCH($A15,'Reference Data'!$A$10:$A$18,0)),"N/A") -> Bath Crystals 400g | C15: =IFERROR(INDEX('Reference Data'!$C$10:$C$18,MATCH($A15,'Reference Data'!$A$10:$A$18,0)),"N/A") -> Body Care | D15: =IFERROR(INDEX('Reference Data'!$D$10:$D$18,MATCH($A15,'Reference Data'!$A$10:$A$18,0)),"N/A") -> Factory F | E15: 60 | F15: 15 | G15: 25 | H15: =SUM(E15:G15) -> 100 | I15: 25 | J15: =IFERROR(H15/I15,"N/A") -> 4 | K15: =IF(J15<$B$4,"High Risk",IF(J15<$B$5,"Medium Risk","Low Risk")) -> Medium Risk | L15: =IFERROR(F15/I15,"N/A") -> 0.6 | M15: =IF(L15<$B$4,"High Risk",IF(L15<$B$5,"Medium Risk","Low Risk")) -> High Risk | N15: =SUMIF('Purchase Orders'!$D$6:$D$11,$A15,'Purchase Orders'!$F$6:$F$11) -> 500 | O15: =SUMIFS('Purchase Orders'!$F$6:$F$11,'Purchase Orders'!$D$6:$D$11,$A15,'Purchase Orders'!$H$6:$H$11,"UK") -> 0
A16: HN-NC-075 | B16: =IFERROR(INDEX('Reference Data'!$B$10:$B$18,MATCH($A16,'Reference Data'!$A$10:$A$18,0)),"N/A") -> Night Cream 75ml | C16: =IFERROR(INDEX('Reference Data'!$C$10:$C$18,MATCH($A16,'Reference Data'!$A$10:$A$18,0)),"N/A") -> Skincare | D16: =IFERROR(INDEX('Reference Data'!$D$10:$D$18,MATCH($A16,'Reference Data'!$A$10:$A$18,0)),"N/A") -> Factory A | E16: 130 | F16: 18 | G16: 55 | H16: =SUM(E16:G16) -> 203 | I16: 40 | J16: =IFERROR(H16/I16,"N/A") -> 5.075 | K16: =IF(J16<$B$4,"High Risk",IF(J16<$B$5,"Medium Risk","Low Risk")) -> Medium Risk | L16: =IFERROR(F16/I16,"N/A") -> 0.45 | M16: =IF(L16<$B$4,"High Risk",IF(L16<$B$5,"Medium Risk","Low Risk")) -> High Risk | N16: =SUMIF('Purchase Orders'!$D$6:$D$11,$A16,'Purchase Orders'!$F$6:$F$11) -> 500 | O16: =SUMIFS('Purchase Orders'!$F$6:$F$11,'Purchase Orders'!$D$6:$D$11,$A16,'Purchase Orders'!$H$6:$H$11,"UK") -> 0
A17: TOTAL | E17: =SUM(E8:E16) -> 1245 | F17: =SUM(F8:F16) -> 221 | G17: =SUM(G8:G16) -> 500 | H17: =SUM(H8:H16) -> 1966 | N17: =SUM(N8:N16) -> 3000 | O17: =SUM(O8:O16) -> 0
A19: Notes & Assumptions
A20: • Product, Category, and Primary Factory are looked up live from the Reference Data Product Catalog — SKU is the only identifying input needed on this sheet.
A21: • Weekly Sell-Through Rate is a single blended rate per SKU (not broken out by warehouse), as provided in source data. UK Weeks of Cover therefore approximates the UK warehouse independently covering total demand at that SKU's overall sell-through rate — read it as a directional risk indicator, not a precise per-location forecast.
A22: • Open PO Qty columns pull live from the Purchase Orders sheet (SUMIF/SUMIFS by SKU), so incoming replenishment updates automatically as POs change.
A23: • Risk thresholds in B4:B5 are editable assumptions — changing them recalculates every Stockout Risk flag on this sheet.

Sheet Reference Data
A1: Reference Data
A3: Fulfillment Warehouses
A4: Warehouse Code | B4: Region / Name | C4: City
A5: US | B5: US West | C5: Los Angeles
A6: UK | B6: UK | C6: Manchester
A7: HK | B7: Asia | C7: Hong Kong
A8: Product Catalog
A9: SKU | B9: Product | C9: Category | D9: Primary Factory
A10: HN-RB-300 | B10: Recovery Balm 300ml | C10: Body Care | D10: Factory A
A11: HN-FS-050 | B11: Face Serum 50ml | C11: Skincare | D11: Factory A
A12: HN-BW-200 | B12: Body Wash 200ml | C12: Body Care | D12: Factory B
A13: HN-HM-100 | B13: Hair Mask 100ml | C13: Hair Care | D13: Factory C
A14: HN-LB-250 | B14: Lip Balm 3-Pack | C14: Skincare | D14: Factory D
A15: HN-SM-150 | B15: Scalp Mist 150ml | C15: Hair Care | D15: Factory C
A16: HN-EO-030 | B16: Essential Oil Blend 30ml | C16: Wellness | D16: Factory E
A17: HN-BC-400 | B17: Bath Crystals 400g | C17: Body Care | D17: Factory F
A18: HN-NC-075 | B18: Night Cream 75ml | C18: Skincare | D18: Factory A
A20: Factory Network
A21: Factory | B21: City | C21: Country | D21: SKUs Produced | E21: MOQ | F21: Production Lead Time (Weeks) | G21: Status
A22: Factory A | B22: Shenzhen | C22: China | D22: HN-RB-300, HN-FS-050, HN-NC-075 | E22: 500 units/SKU | F22: 3 | G22: Active — reliable, primary partner
A23: Factory B | B23: Chiang Mai | C23: Thailand | D23: HN-BW-200 | E23: 400 units | F23: 2.5 | G23: Active — reliable
A24: Factory C | B24: Jakarta | C24: Indonesia | D24: HN-HM-100, HN-SM-150 | E24: 300 units/SKU | F24: 3 | G24: Active — occasional delays
A25: Factory D | B25: Taipei | C25: Taiwan | D25: HN-LB-250 | E25: 1,000 units | F25: 2 | G25: Active — high MOQ but fast
A26: Factory E | B26: Chiang Mai | C26: Thailand | D26: HN-EO-030 | E26: 200 units | F26: 2 | G26: New — first PO in progress
A27: Factory F | B27: Ho Chi Minh City | C27: Vietnam | D27: HN-BC-400 | E27: 500 units | F27: 4 | G27: Active — long lead time
A29: Shipping Lead Times
A30: Origin (Factory City) | B30: Destination (Warehouse Code) | C30: Sea Freight (Weeks) | D30: Air Freight (Days) | E30: Air Freight (Weeks) | F30: Route Key
A31: Shenzhen | B31: US | C31: 3 | D31: 5 | E31: =D31/7 -> 0.71428571 | F31: =A31&"|"&B31 -> Shenzhen|US
A32: Shenzhen | B32: UK | C32: 5 | D32: 7 | E32: =D32/7 -> 1 | F32: =A32&"|"&B32 -> Shenzhen|UK
A33: Shenzhen | B33: HK | C33: 0.28571429 | D33: 1 | E33: =D33/7 -> 0.14285714 | F33: =A33&"|"&B33 -> Shenzhen|HK
A34: Chiang Mai | B34: US | C34: 4.5 | D34: 6 | E34: =D34/7 -> 0.85714286 | F34: =A34&"|"&B34 -> Chiang Mai|US
A35: Chiang Mai | B35: UK | C35: 4.5 | D35: 7 | E35: =D35/7 -> 1 | F35: =A35&"|"&B35 -> Chiang Mai|UK
A36: Chiang Mai | B36: HK | C36: 4 | D36: 2 | E36: =D36/7 -> 0.28571429 | F36: =A36&"|"&B36 -> Chiang Mai|HK
A37: Jakarta | B37: US | C37: 4 | D37: 6 | E37: =D37/7 -> 0.85714286 | F37: =A37&"|"&B37 -> Jakarta|US
A38: Jakarta | B38: UK | C38: 5 | D38: 7 | E38: =D38/7 -> 1 | F38: =A38&"|"&B38 -> Jakarta|UK
A39: Jakarta | B39: HK | C39: 4 | D39: 2 | E39: =D39/7 -> 0.28571429 | F39: =A39&"|"&B39 -> Jakarta|HK
A40: Taipei | B40: US | C40: 3 | D40: 4 | E40: =D40/7 -> 0.57142857 | F40: =A40&"|"&B40 -> Taipei|US
A41: Taipei | B41: UK | C41: 5 | D41: 6 | E41: =D41/7 -> 0.85714286 | F41: =A41&"|"&B41 -> Taipei|UK
A42: Taipei | B42: HK | C42: 0.28571429 | D42: 1 | E42: =D42/7 -> 0.14285714 | F42: =A42&"|"&B42 -> Taipei|HK
... A45: Ho Chi Minh City | B45: HK | C45: 3 | D45: 1 | E45: =D45/7 -> 0.14285714 | F45: =A45&"|"&B45 -> Ho Chi Minh City|HK
...
