Workbook

Sheet Summary
A1: UK Restock Plan — Summary
A2: Extracted from the Supply Chain Tracker. All figures are calculated live from the sheets in this workbook.
A4: Key Alerts
A5: ="UK Warehouse Shipping: "&IF(COUNTIF('Purchase Orders'!H6:H11,"UK")=0,"No open purchase orders are currently shipping to the UK warehouse.",COUNTIF('Purchase Orders'!H6:H11,"UK")&" open PO(s) shipping to UK.") -> UK Warehouse Shipping: No open purchase orders are currently shipping to the UK warehouse.
A6: ="UK Stockout Risk: "&COUNTIF('Inventory & Coverage'!M8:M16,"High Risk")&" of "&COUNTA('Inventory & Coverage'!A8:A16)&" SKUs are at High stockout risk in the UK warehouse; "&SUMPRODUCT(('Inventory & Coverage'!M8:M16="High Risk")*('Inventory & Coverage'!O8:O16=0))&" of those currently have zero replenishment in transit to UK." -> UK Stockout Risk: 9 of 9 SKUs are at High stockout risk in the UK warehouse; 9 of those currently have zero replenishment in transit to UK.
A7: ="Purchase Order Risk: "&COUNTIF('Purchase Orders'!O6:O11,"High Risk")&" of "&COUNTA('Purchase Orders'!A6:A11)&" open PO(s) are flagged High Risk and require follow-up." -> Purchase Order Risk: 2 of 6 open PO(s) are flagged High Risk and require follow-up.
A8: ="Retail Partner Demand: "&IF('UK Restock Plan'!K20=0,"No opening stocking order quantities from the 3 new UK retail partners have been entered yet (UK Restock Plan column K) — restock quantities below currently reflect DTC demand only and are likely understated.","Retail partner stocking quantities are entered — restock quantities include "&'UK Restock Plan'!K20&" units of retail launch stock.") -> Retail Partner Demand: No opening stocking order quantities from the 3 new UK retail partners have been entered yet (UK Restock Plan column K) — restock quantities below currently reflect DTC demand only and are likely understated.
A10: UK Launch Readiness
A11: UK Launch Date | B11: ='UK Restock Plan'!B4 -> 46286
A12: Weeks Until Launch | B12: ='UK Restock Plan'!B8 -> 5.8571429
A13: Retail Partner Stocking Qty Entered (Units) | B13: ='UK Restock Plan'!K20 -> 0
A14: Total UK Restock Units Needed | B14: ='UK Restock Plan'!O20 -> 4600
A15: SKUs On Track (Sea Freight) | B15: =COUNTIF('UK Restock Plan'!W11:W19,"On Track") -> 0
A16: SKUs Needing Expedited Air | B16: =COUNTIF('UK Restock Plan'!W11:W19,"Expedite Required") -> 9
A17: SKUs Critical — May Miss Launch | B17: =COUNTIF('UK Restock Plan'!W11:W19,"Critical — May Miss Launch") -> 0
A18: Open POs Needing Follow-Up | B18: =COUNTIF('PO Follow-Ups'!J6:J11,"Yes") -> 3
A20: Notes & Assumptions
A21: • This is a standalone extract of the UK Restock Plan and PO Follow-Ups from the Supply Chain Tracker workbook, with the supporting Purchase Orders, Inventory & Coverage, and Reference Data carried along so every formula still resolves independently of that file.
A22: • See the UK Restock Plan tab to edit the Launch Date / Target Weeks of Cover assumptions — this Summary and every dependent formula recalculates from there.
A23: • Get the initial stocking order quantities from the 3 new UK retail partners and enter them per SKU in UK Restock Plan column K as soon as they're known — until then, every recommended order quantity on this sheet reflects DTC demand only.

Sheet UK Restock Plan
A1: UK Restock Plan
A3: Launch Assumptions (editable):
A4: UK Launch Date | B4: 46286 | C4: 3 new UK retail partners launch in 6 weeks (from 2026-08-10) — edit if the date shifts
A5: Target Weeks of Cover at Launch | B5: 10 | C5: EDIT ME — desired DTC buffer of stock at launch (retail partner stocking is separate, see column K below)
A6: New UK Retail Partners Launching | B6: 3 | C6: Informational — their per-SKU opening stocking orders go in column K (Retail Partner Launch Stocking Qty) once known
A7: Today's Date (reference) | B7: =TODAY() -> 46245
A8: Weeks Until Launch | B8: =($B$4-$B$7)/7 -> 5.8571429
A10: SKU | B10: Product | C10: Factory | D10: Factory City | E10: UK On-Hand Qty | F10: Weekly Sell- Through Rate (DTC only) | G10: Open PO Qty to UK | H10: Current UK Weeks of Cover | I10: Current UK Stockout Risk | J10: Projected UK On-Hand at Launch | K10: Retail Partner Launch Stocking Qty (Units) | L10: Target Qty at Launch | M10: Order Qty Needed (Pre-MOQ) | N10: Factory MOQ (Units) | O10: Recommended Order Qty | P10: Production Lead Time (Wks) | Q10: Sea Transit to UK (Wks) | R10: Air Transit to UK (Wks) | S10: Total Lead Time — Sea | T10: Total Lead Time — Air | U10: Recommended Ship Method | V10: Order-By Date | W10: Launch Readiness
A11: ='Inventory & Coverage'!A8 -> HN-RB-300 | B11: ='Inventory & Coverage'!B8 -> Recovery Balm 300ml | C11: ='Inventory & Coverage'!D8 -> Factory A | D11: =IFERROR(INDEX('Reference Data'!$B$22:$B$27,MATCH($C11,'Reference Data'!$A$22:$A$27,0)),"N/A") -> Shenzhen | E11: ='Inventory & Coverage'!F8 -> 35 | F11: ='Inventory & Coverage'!I8 -> 75 | G11: ='Inventory & Coverage'!O8 -> 0 | H11: ='Inventory & Coverage'!L8 -> 0.46666667 | I11: ='Inventory & Coverage'!M8 -> High Risk | J11: =MAX($E11-$F11*$B$8,0)+$G11 -> 0 | K11: 0 | L11: =$F11*$B$5+$K11 -> 750 | M11: =MAX($L11-$J11,0) -> 750 | N11: =IFERROR(INDEX('Reference Data'!$F$22:$F$27,MATCH($C11,'Reference Data'!$A$22:$A$27,0)),"N/A") -> 500 | O11: =IF($M11<=0,0,MAX($M11,$N11)) -> 750 | P11: =IFERROR(INDEX('Reference Data'!$G$22:$G$27,MATCH($C11,'Reference Data'!$A$22:$A$27,0)),"N/A") -> 3 | Q11: =IFERROR(INDEX('Reference Data'!$C$31:$C$45,MATCH($D11&"|UK",'Reference Data'!$F$31:$F$45,0)),"N/A") -> 5 | R11: =IFERROR(INDEX('Reference Data'!$E$31:$E$45,MATCH($D11&"|UK",'Reference Data'!$F$31:$F$45,0)),"N/A") -> 1 | S11: =$P11+$Q11 -> 8 | T11: =$P11+$R11 -> 4 | U11: =IF($O11=0,"No Order Needed",IF($S11<=$B$8,"Sea",IF($T11<=$B$8,"Air — Expedite","Air — Still At Risk"))) -> Air — Expedite | V11: =IF($O11=0,"N/A",$B$4-IF($U11="Sea",$S11,$T11)*7) -> 46258 | W11: =IF($O11=0,"No Restock Needed",IF($U11="Sea","On Track",IF($U11="Air — Expedite","Expedite Required","Critical — May Miss Launch"))) -> Expedite Required
A12: ='Inventory & Coverage'!A9 -> HN-FS-050 | B12: ='Inventory & Coverage'!B9 -> Face Serum 50ml | C12: ='Inventory & Coverage'!D9 -> Factory A | D12: =IFERROR(INDEX('Reference Data'!$B$22:$B$27,MATCH($C12,'Reference Data'!$A$22:$A$27,0)),"N/A") -> Shenzhen | E12: ='Inventory & Coverage'!F9 -> 20 | F12: ='Inventory & Coverage'!I9 -> 45 | G12: ='Inventory & Coverage'!O9 -> 0 | H12: ='Inventory & Coverage'!L9 -> 0.44444444 | I12: ='Inventory & Coverage'!M9 -> High Risk | J12: =MAX($E12-$F12*$B$8,0)+$G12 -> 0 | K12: 0 | L12: =$F12*$B$5+$K12 -> 450 | M12: =MAX($L12-$J12,0) -> 450 | N12: =IFERROR(INDEX('Reference Data'!$F$22:$F$27,MATCH($C12,'Reference Data'!$A$22:$A$27,0)),"N/A") -> 500 | O12: =IF($M12<=0,0,MAX($M12,$N12)) -> 500 | P12: =IFERROR(INDEX('Reference Data'!$G$22:$G$27,MATCH($C12,'Reference Data'!$A$22:$A$27,0)),"N/A") -> 3 | Q12: =IFERROR(INDEX('Reference Data'!$C$31:$C$45,MATCH($D12&"|UK",'Reference Data'!$F$31:$F$45,0)),"N/A") -> 5 | R12: =IFERROR(INDEX('Reference Data'!$E$31:$E$45,MATCH($D12&"|UK",'Reference Data'!$F$31:$F$45,0)),"N/A") -> 1 | S12: =$P12+$Q12 -> 8 | T12: =$P12+$R12 -> 4 | U12: =IF($O12=0,"No Order Needed",IF($S12<=$B$8,"Sea",IF($T12<=$B$8,"Air — Expedite","Air — Still At Risk"))) -> Air — Expedite | V12: =IF($O12=0,"N/A",$B$4-IF($U12="Sea",$S12,$T12)*7) -> 46258 | W12: =IF($O12=0,"No Restock Needed",IF($U12="Sea","On Track",IF($U12="Air — Expedite","Expedite Required","Critical — May Miss Launch"))) -> Expedite Required
A13: ='Inventory & Coverage'!A10 -> HN-BW-200 | B13: ='Inventory & Coverage'!B10 -> Body Wash 200ml | C13: ='Inventory & Coverage'!D10 -> Factory B | D13: =IFERROR(INDEX('Reference Data'!$B$22:$B$27,MATCH($C13,'Reference Data'!$A$22:$A$27,0)),"N/A") -> Chiang Mai | E13: ='Inventory & Coverage'!F10 -> 50 | F13: ='Inventory & Coverage'!I10 -> 55 | G13: ='Inventory & Coverage'!O10 -> 0 | H13: ='Inventory & Coverage'!L10 -> 0.90909091 | I13: ='Inventory & Coverage'!M10 -> High Risk | J13: =MAX($E13-$F13*$B$8,0)+$G13 -> 0 | K13: 0 | L13: =$F13*$B$5+$K13 -> 550 | M13: =MAX($L13-$J13,0) -> 550 | N13: =IFERROR(INDEX('Reference Data'!$F$22:$F$27,MATCH($C13,'Reference Data'!$A$22:$A$27,0)),"N/A") -> 400 | O13: =IF($M13<=0,0,MAX($M13,$N13)) -> 550 | P13: =IFERROR(INDEX('Reference Data'!$G$22:$G$27,MATCH($C13,'Reference Data'!$A$22:$A$27,0)),"N/A") -> 2.5 | Q13: =IFERROR(INDEX('Reference Data'!$C$31:$C$45,MATCH($D13&"|UK",'Reference Data'!$F$31:$F$45,0)),"N/A") -> 4.5 | R13: =IFERROR(INDEX('Reference Data'!$E$31:$E$45,MATCH($D13&"|UK",'Reference Data'!$F$31:$F$45,0)),"N/A") -> 1 | S13: =$P13+$Q13 -> 7 | T13: =$P13+$R13 -> 3.5 | U13: =IF($O13=0,"No Order Needed",IF($S13<=$B$8,"Sea",IF($T13<=$B$8,"Air — Expedite","Air — Still At Risk"))) -> Air — Expedite | V13: =IF($O13=0,"N/A",$B$4-IF($U13="Sea",$S13,$T13)*7) -> 46261.5 | W13: =IF($O13=0,"No Restock Needed",IF($U13="Sea","On Track",IF($U13="Air — Expedite","Expedite Required","Critical — May Miss Launch"))) -> Expedite Required
A14: ='Inventory & Coverage'!A11 -> HN-HM-100 | B14: ='Inventory & Coverage'!B11 -> Hair Mask 100ml | C14: ='Inventory & Coverage'!D11 -> Factory C | D14: =IFERROR(INDEX('Reference Data'!$B$22:$B$27,MATCH($C14,'Reference Data'!$A$22:$A$27,0)),"N/A") -> Jakarta | E14: ='Inventory & Coverage'!F11 -> 25 | F14: ='Inventory & Coverage'!I11 -> 30 | G14: ='Inventory & Coverage'!O11 -> 0 | H14: ='Inventory & Coverage'!L11 -> 0.83333333 | I14: ='Inventory & Coverage'!M11 -> High Risk | J14: =MAX($E14-$F14*$B$8,0)+$G14 -> 0 | K14: 0 | L14: =$F14*$B$5+$K14 -> 300 | M14: =MAX($L14-$J14,0) -> 300 | N14: =IFERROR(INDEX('Reference Data'!$F$22:$F$27,MATCH($C14,'Reference Data'!$A$22:$A$27,0)),"N/A") -> 300 | O14: =IF($M14<=0,0,MAX($M14,$N14)) -> 300 | P14: =IFERROR(INDEX('Reference Data'!$G$22:$G$27,MATCH($C14,'Reference Data'!$A$22:$A$27,0)),"N/A") -> 3 | Q14: =IFERROR(INDEX('Reference Data'!$C$31:$C$45,MATCH($D14&"|UK",'Reference Data'!$F$31:$F$45,0)),"N/A") -> 5 | R14: =IFERROR(INDEX('Reference Data'!$E$31:$E$45,MATCH($D14&"|UK",'Reference Data'!$F$31:$F$45,0)),"N/A") -> 1 | S14: =$P14+$Q14 -> 8 | T14: =$P14+$R14 -> 4 | U14: =IF($O14=0,"No Order Needed",IF($S14<=$B$8,"Sea",IF($T14<=$B$8,"Air — Expedite","Air — Still At Risk"))) -> Air — Expedite | V14: =IF($O14=0,"N/A",$B$4-IF($U14="Sea",$S14,$T14)*7) -> 46258 | W14: =IF($O14=0,"No Restock Needed",IF($U14="Sea","On Track",IF($U14="Air — Expedite","Expedite Required","Critical — May Miss Launch"))) -> Expedite Required
A15: ='Inventory & Coverage'!A12 -> HN-LB-250 | B15: ='Inventory & Coverage'!B12 -> Lip Balm 3-Pack | C15: ='Inventory & Coverage'!D12 -> Factory D | D15: =IFERROR(INDEX('Reference Data'!$B$22:$B$27,MATCH($C15,'Reference Data'!$A$22:$A$27,0)),"N/A") -> Taipei | E15: ='Inventory & Coverage'!F12 -> 40 | F15: ='Inventory & Coverage'!I12 -> 60 | G15: ='Inventory & Coverage'!O12 -> 0 | H15: ='Inventory & Coverage'!L12 -> 0.66666667 | I15: ='Inventory & Coverage'!M12 -> High Risk | J15: =MAX($E15-$F15*$B$8,0)+$G15 -> 0 | K15: 0 | L15: =$F15*$B$5+$K15 -> 600 | M15: =MAX($L15-$J15,0) -> 600 | N15: =IFERROR(INDEX('Reference Data'!$F$22:$F$27,MATCH($C15,'Reference Data'!$A$22:$A$27,0)),"N/A") -> 1000 | O15: =IF($M15<=0,0,MAX($M15,$N15)) -> 1000 | P15: =IFERROR(INDEX('Reference Data'!$G$22:$G$27,MATCH($C15,'Reference Data'!$A$22:$A$27,0)),"N/A") -> 2 | Q15: =IFERROR(INDEX('Reference Data'!$C$31:$C$45,MATCH($D15&"|UK",'Reference Data'!$F$31:$F$45,0)),"N/A") -> 5 | R15: =IFERROR(INDEX('Reference Data'!$E$31:$E$45,MATCH($D15&"|UK",'Reference Data'!$F$31:$F$45,0)),"N/A") -> 0.85714286 | S15: =$P15+$Q15 -> 7 | T15: =$P15+$R15 -> 2.8571429 | U15: =IF($O15=0,"No Order Needed",IF($S15<=$B$8,"Sea",IF($T15<=$B$8,"Air — Expedite","Air — Still At Risk"))) -> Air — Expedite | V15: =IF($O15=0,"N/A",$B$4-IF($U15="Sea",$S15,$T15)*7) -> 46266 | W15: =IF($O15=0,"No Restock Needed",IF($U15="Sea","On Track",IF($U15="Air — Expedite","Expedite Required","Critical — May Miss Launch"))) -> Expedite Required
A16: ='Inventory & Coverage'!A13 -> HN-SM-150 | B16: ='Inventory & Coverage'!B13 -> Scalp Mist 150ml | C16: ='Inventory & Coverage'!D13 -> Factory C | D16: =IFERROR(INDEX('Reference Data'!$B$22:$B$27,MATCH($C16,'Reference Data'!$A$22:$A$27,0)),"N/A") -> Jakarta | E16: ='Inventory & Coverage'!F13 -> 10 | F16: ='Inventory & Coverage'!I13 -> 20 | G16: ='Inventory & Coverage'!O13 -> 0 | H16: ='Inventory & Coverage'!L13 -> 0.5 | I16: ='Inventory & Coverage'!M13 -> High Risk | J16: =MAX($E16-$F16*$B$8,0)+$G16 -> 0 | K16: 0 | L16: =$F16*$B$5+$K16 -> 200 | M16: =MAX($L16-$J16,0) -> 200 | N16: =IFERROR(INDEX('Reference Data'!$F$22:$F$27,MATCH($C16,'Reference Data'!$A$22:$A$27,0)),"N/A") -> 300 | O16: =IF($M16<=0,0,MAX($M16,$N16)) -> 300 | P16: =IFERROR(INDEX('Reference Data'!$G$22:$G$27,MATCH($C16,'Reference Data'!$A$22:$A$27,0)),"N/A") -> 3 | Q16: =IFERROR(INDEX('Reference Data'!$C$31:$C$45,MATCH($D16&"|UK",'Reference Data'!$F$31:$F$45,0)),"N/A") -> 5 | R16: =IFERROR(INDEX('Reference Data'!$E$31:$E$45,MATCH($D16&"|UK",'Reference Data'!$F$31:$F$45,0)),"N/A") -> 1 | S16: =$P16+$Q16 -> 8 | T16: =$P16+$R16 -> 4 | U16: =IF($O16=0,"No Order Needed",IF($S16<=$B$8,"Sea",IF($T16<=$B$8,"Air — Expedite","Air — Still At Risk"))) -> Air — Expedite | V16: =IF($O16=0,"N/A",$B$4-IF($U16="Sea",$S16,$T16)*7) -> 46258 | W16: =IF($O16=0,"No Restock Needed",IF($U16="Sea","On Track",IF($U16="Air — Expedite","Expedite Required","Critical — May Miss Launch"))) -> Expedite Required
A17: ='Inventory & Coverage'!A14 -> HN-EO-030 | B17: ='Inventory & Coverage'!B14 -> Essential Oil Blend 30ml | C17: ='Inventory & Coverage'!D14 -> Factory E | D17: =IFERROR(INDEX('Reference Data'!$B$22:$B$27,MATCH($C17,'Reference Data'!$A$22:$A$27,0)),"N/A") -> Chiang Mai | E17: ='Inventory & Coverage'!F14 -> 8 | F17: ='Inventory & Coverage'!I14 -> 15 | G17: ='Inventory & Coverage'!O14 -> 0 | H17: ='Inventory & Coverage'!L14 -> 0.53333333 | I17: ='Inventory & Coverage'!M14 -> High Risk | J17: =MAX($E17-$F17*$B$8,0)+$G17 -> 0 | K17: 0 | L17: =$F17*$B$5+$K17 -> 150 | M17: =MAX($L17-$J17,0) -> 150 | N17: =IFERROR(INDEX('Reference Data'!$F$22:$F$27,MATCH($C17,'Reference Data'!$A$22:$A$27,0)),"N/A") -> 200 | O17: =IF($M17<=0,0,MAX($M17,$N17)) -> 200 | P17: =IFERROR(INDEX('Reference Data'!$G$22:$G$27,MATCH($C17,'Reference Data'!$A$22:$A$27,0)),"N/A") -> 2 | Q17: =IFERROR(INDEX('Reference Data'!$C$31:$C$45,MATCH($D17&"|UK",'Reference Data'!$F$31:$F$45,0)),"N/A") -> 4.5 | R17: =IFERROR(INDEX('Reference Data'!$E$31:$E$45,MATCH($D17&"|UK",'Reference Data'!$F$31:$F$45,0)),"N/A") -> 1 | S17: =$P17+$Q17 -> 6.5 | T17: =$P17+$R17 -> 3 | U17: =IF($O17=0,"No Order Needed",IF($S17<=$B$8,"Sea",IF($T17<=$B$8,"Air — Expedite","Air — Still At Risk"))) -> Air — Expedite | V17: =IF($O17=0,"N/A",$B$4-IF($U17="Sea",$S17,$T17)*7) -> 46265 | W17: =IF($O17=0,"No Restock Needed",IF($U17="Sea","On Track",IF($U17="Air — Expedite","Expedite Required","Critical — May Miss Launch"))) -> Expedite Required
A18: ='Inventory & Coverage'!A15 -> HN-BC-400 | B18: ='Inventory & Coverage'!B15 -> Bath Crystals 400g | C18: ='Inventory & Coverage'!D15 -> Factory F | D18: =IFERROR(INDEX('Reference Data'!$B$22:$B$27,MATCH($C18,'Reference Data'!$A$22:$A$27,0)),"N/A") -> Ho Chi Minh City | E18: ='Inventory & Coverage'!F15 -> 15 | F18: ='Inventory & Coverage'!I15 -> 25 | G18: ='Inventory & Coverage'!O15 -> 0 | H18: ='Inventory & Coverage'!L15 -> 0.6 | I18: ='Inventory & Coverage'!M15 -> High Risk | J18: =MAX($E18-$F18*$B$8,0)+$G18 -> 0 | K18: 0 | L18: =$F18*$B$5+$K18 -> 250 | M18: =MAX($L18-$J18,0) -> 250 | N18: =IFERROR(INDEX('Reference Data'!$F$22:$F$27,MATCH($C18,'Reference Data'!$A$22:$A$27,0)),"N/A") -> 500 | O18: =IF($M18<=0,0,MAX($M18,$N18)) -> 500 | P18: =IFERROR(INDEX('Reference Data'!$G$22:$G$27,MATCH($C18,'Reference Data'!$A$22:$A$27,0)),"N/A") -> 4 | Q18: =IFERROR(INDEX('Reference Data'!$C$31:$C$45,MATCH($D18&"|UK",'Reference Data'!$F$31:$F$45,0)),"N/A") -> 5 | R18: =IFERROR(INDEX('Reference Data'!$E$31:$E$45,MATCH($D18&"|UK",'Reference Data'!$F$31:$F$45,0)),"N/A") -> 1 | S18: =$P18+$Q18 -> 9 | T18: =$P18+$R18 -> 5 | U18: =IF($O18=0,"No Order Needed",IF($S18<=$B$8,"Sea",IF($T18<=$B$8,"Air — Expedite","Air — Still At Risk"))) -> Air — Expedite | V18: =IF($O18=0,"N/A",$B$4-IF($U18="Sea",$S18,$T18)*7) -> 46251 | W18: =IF($O18=0,"No Restock Needed",IF($U18="Sea","On Track",IF($U18="Air — Expedite","Expedite Required","Critical — May Miss Launch"))) -> Expedite Required
A19: ='Inventory & Coverage'!A16 -> HN-NC-075 | B19: ='Inventory & Coverage'!B16 -> Night Cream 75ml | C19: ='Inventory & Coverage'!D16 -> Factory A | D19: =IFERROR(INDEX('Reference Data'!$B$22:$B$27,MATCH($C19,'Reference Data'!$A$22:$A$27,0)),"N/A") -> Shenzhen | E19: ='Inventory & Coverage'!F16 -> 18 | F19: ='Inventory & Coverage'!I16 -> 40 | G19: ='Inventory & Coverage'!O16 -> 0 | H19: ='Inventory & Coverage'!L16 -> 0.45 | I19: ='Inventory & Coverage'!M16 -> High Risk | J19: =MAX($E19-$F19*$B$8,0)+$G19 -> 0 | K19: 0 | L19: =$F19*$B$5+$K19 -> 400 | M19: =MAX($L19-$J19,0) -> 400 | N19: =IFERROR(INDEX('Reference Data'!$F$22:$F$27,MATCH($C19,'Reference Data'!$A$22:$A$27,0)),"N/A") -> 500 | O19: =IF($M19<=0,0,MAX($M19,$N19)) -> 500 | P19: =IFERROR(INDEX('Reference Data'!$G$22:$G$27,MATCH($C19,'Reference Data'!$A$22:$A$27,0)),"N/A") -> 3 | Q19: =IFERROR(INDEX('Reference Data'!$C$31:$C$45,MATCH($D19&"|UK",'Reference Data'!$F$31:$F$45,0)),"N/A") -> 5 | R19: =IFERROR(INDEX('Reference Data'!$E$31:$E$45,MATCH($D19&"|UK",'Reference Data'!$F$31:$F$45,0)),"N/A") -> 1 | S19: =$P19+$Q19 -> 8 | T19: =$P19+$R19 -> 4 | U19: =IF($O19=0,"No Order Needed",IF($S19<=$B$8,"Sea",IF($T19<=$B$8,"Air — Expedite","Air — Still At Risk"))) -> Air — Expedite | V19: =IF($O19=0,"N/A",$B$4-IF($U19="Sea",$S19,$T19)*7) -> 46258 | W19: =IF($O19=0,"No Restock Needed",IF($U19="Sea","On Track",IF($U19="Air — Expedite","Expedite Required","Critical — May Miss Launch"))) -> Expedite Required
A20: TOTAL | K20: =SUM(K11:K19) -> 0 | O20: =SUM(O11:O19) -> 4600
A22: Notes & Assumptions
A23: • SKU, Product, Factory, and current UK inventory/coverage figures are linked live from Inventory & Coverage — this sheet has no re-entered source data.
A24: • IMPORTANT GAP: Weekly Sell-Through Rate (column F) is the DTC-only rate from the source data. It does not include demand from the 3 new UK retail partners. Column K (Retail Partner Launch Stocking Qty) is where their opening stocking orders should be entered per SKU once known — it currently defaults to 0, so Target Qty at Launch and every recommendation to its right currently reflect DTC demand ONLY and likely understate what's actually needed for launch.
A25: • Projected UK On-Hand at Launch assumes steady depletion at the current (DTC-only) Weekly Sell-Through Rate between today and the Launch Date, plus any PO quantity already open to UK (column G) landing before launch. It does not assume the newly recommended order below arrives in time — that is what the lead-time/readiness columns to the right test.
A26: • Recommended Order Qty rounds the pre-MOQ need up to the factory's MOQ (a partial-MOQ need still requires ordering a full MOQ batch).
A27: • Recommended Ship Method / Launch Readiness compare each lead-time option (Production Lead Time + Sea or Air transit to UK) against Weeks Until Launch: Sea if it fits, Air if only Air fits, otherwise flagged Critical even with Air.
A28: • Order-By Date = Launch Date minus the recommended method's total lead time. If this date is already in the past, that order is overdue and should be placed immediately.
A29: • Change the Launch Date, Target Weeks of Cover, or any Retail Partner Launch Stocking Qty and every recommendation on this sheet recalculates.

Sheet PO Follow-Ups
A1: PO Follow-Ups
A3: All fields link live from Purchase Orders / Inventory & Coverage — no PO data is re-entered here.
A5: PO # | B5: Factory | C5: SKU | D5: Product | E5: Qty | F5: Status | G5: PO Risk Flag | H5: Destination Warehouse | I5: Affects UK Restock? | J5: Follow-Up Needed? | K5: Recommended Action | L5: Priority
A6: ='Purchase Orders'!A6 -> PO-410 | B6: ='Purchase Orders'!B6 -> Factory A | C6: ='Purchase Orders'!D6 -> HN-RB-300 | D6: ='Purchase Orders'!E6 -> Recovery Balm 300ml | E6: ='Purchase Orders'!F6 -> 500 | F6: ='Purchase Orders'!G6 -> In production — on track | G6: ='Purchase Orders'!O6 -> Low Risk | H6: ='Purchase Orders'!H6 -> HK | I6: =IF(IFERROR(INDEX('Inventory & Coverage'!$M$8:$M$16,MATCH($C6,'Inventory & Coverage'!$A$8:$A$16,0)),"")="High Risk","Yes — UK Critical SKU","No") -> Yes — UK Critical SKU | J6: =IF($G6="Low Risk","No","Yes") -> No | K6: =IF(ISNUMBER(SEARCH("delayed",$F6)),"Contact factory for a revised production timeline. If this is a UK-critical SKU, evaluate air freight or a backup factory to recover schedule.",IF(ISNUMBER(SEARCH("Unconfirmed",$F6)),"Escalate to factory immediately — no confirmation received. Confirm the production slot or reallocate the PO to a backup factory.",IF(ISNUMBER(SEARCH("Completed",$F6)),"Issue shipping instructions now. Goods are finished and awaiting dispatch — assign a destination and carrier immediately to avoid storage delays.",IF(ISNUMBER(SEARCH("on track",$F6)),"No follow-up needed — monitor for on-time delivery.","Review PO status manually.")))) -> No follow-up needed — monitor for on-time delivery. | L6: =IF(AND($G6<>"Low Risk",$I6="Yes — UK Critical SKU"),"Urgent — UK Launch Impact",IF($G6="High Risk","High",IF($G6="Medium Risk","Medium","Low"))) -> Low
A7: ='Purchase Orders'!A7 -> PO-411 | B7: ='Purchase Orders'!B7 -> Factory A | C7: ='Purchase Orders'!D7 -> HN-NC-075 | D7: ='Purchase Orders'!E7 -> Night Cream 75ml | E7: ='Purchase Orders'!F7 -> 500 | F7: ='Purchase Orders'!G7 -> In production — on track | G7: ='Purchase Orders'!O7 -> Low Risk | H7: ='Purchase Orders'!H7 -> US | I7: =IF(IFERROR(INDEX('Inventory & Coverage'!$M$8:$M$16,MATCH($C7,'Inventory & Coverage'!$A$8:$A$16,0)),"")="High Risk","Yes — UK Critical SKU","No") -> Yes — UK Critical SKU | J7: =IF($G7="Low Risk","No","Yes") -> No | K7: =IF(ISNUMBER(SEARCH("delayed",$F7)),"Contact factory for a revised production timeline. If this is a UK-critical SKU, evaluate air freight or a backup factory to recover schedule.",IF(ISNUMBER(SEARCH("Unconfirmed",$F7)),"Escalate to factory immediately — no confirmation received. Confirm the production slot or reallocate the PO to a backup factory.",IF(ISNUMBER(SEARCH("Completed",$F7)),"Issue shipping instructions now. Goods are finished and awaiting dispatch — assign a destination and carrier immediately to avoid storage delays.",IF(ISNUMBER(SEARCH("on track",$F7)),"No follow-up needed — monitor for on-time delivery.","Review PO status manually.")))) -> No follow-up needed — monitor for on-time delivery. | L7: =IF(AND($G7<>"Low Risk",$I7="Yes — UK Critical SKU"),"Urgent — UK Launch Impact",IF($G7="High Risk","High",IF($G7="Medium Risk","Medium","Low"))) -> Low
A8: ='Purchase Orders'!A8 -> PO-412 | B8: ='Purchase Orders'!B8 -> Factory C | C8: ='Purchase Orders'!D8 -> HN-HM-100 | D8: ='Purchase Orders'!E8 -> Hair Mask 100ml | E8: ='Purchase Orders'!F8 -> 300 | F8: ='Purchase Orders'!G8 -> Production delayed — raw material shortage | G8: ='Purchase Orders'!O8 -> High Risk | H8: ='Purchase Orders'!H8 -> Unknown | I8: =IF(IFERROR(INDEX('Inventory & Coverage'!$M$8:$M$16,MATCH($C8,'Inventory & Coverage'!$A$8:$A$16,0)),"")="High Risk","Yes — UK Critical SKU","No") -> Yes — UK Critical SKU | J8: =IF($G8="Low Risk","No","Yes") -> Yes | K8: =IF(ISNUMBER(SEARCH("delayed",$F8)),"Contact factory for a revised production timeline. If this is a UK-critical SKU, evaluate air freight or a backup factory to recover schedule.",IF(ISNUMBER(SEARCH("Unconfirmed",$F8)),"Escalate to factory immediately — no confirmation received. Confirm the production slot or reallocate the PO to a backup factory.",IF(ISNUMBER(SEARCH("Completed",$F8)),"Issue shipping instructions now. Goods are finished and awaiting dispatch — assign a destination and carrier immediately to avoid storage delays.",IF(ISNUMBER(SEARCH("on track",$F8)),"No follow-up needed — monitor for on-time delivery.","Review PO status manually.")))) -> Contact factory for a revised production timeline. If this is a UK-critical SKU, evaluate air freight or a backup factory to recover schedule. | L8: =IF(AND($G8<>"Low Risk",$I8="Yes — UK Critical SKU"),"Urgent — UK Launch Impact",IF($G8="High Risk","High",IF($G8="Medium Risk","Medium","Low"))) -> Urgent — UK Launch Impact
A9: ='Purchase Orders'!A9 -> PO-413 | B9: ='Purchase Orders'!B9 -> Factory D | C9: ='Purchase Orders'!D9 -> HN-LB-250 | D9: ='Purchase Orders'!E9 -> Lip Balm 3-Pack | E9: ='Purchase Orders'!F9 -> 1000 | F9: ='Purchase Orders'!G9 -> Completed — ready for pickup | G9: ='Purchase Orders'!O9 -> Medium Risk | H9: ='Purchase Orders'!H9 -> Unknown | I9: =IF(IFERROR(INDEX('Inventory & Coverage'!$M$8:$M$16,MATCH($C9,'Inventory & Coverage'!$A$8:$A$16,0)),"")="High Risk","Yes — UK Critical SKU","No") -> Yes — UK Critical SKU | J9: =IF($G9="Low Risk","No","Yes") -> Yes | K9: =IF(ISNUMBER(SEARCH("delayed",$F9)),"Contact factory for a revised production timeline. If this is a UK-critical SKU, evaluate air freight or a backup factory to recover schedule.",IF(ISNUMBER(SEARCH("Unconfirmed",$F9)),"Escalate to factory immediately — no confirmation received. Confirm the production slot or reallocate the PO to a backup factory.",IF(ISNUMBER(SEARCH("Completed",$F9)),"Issue shipping instructions now. Goods are finished and awaiting dispatch — assign a destination and carrier immediately to avoid storage delays.",IF(ISNUMBER(SEARCH("on track",$F9)),"No follow-up needed — monitor for on-time delivery.","Review PO status manually.")))) -> Issue shipping instructions now. Goods are finished and awaiting dispatch — assign a destination and carrier immediately to avoid storage delays. | L9: =IF(AND($G9<>"Low Risk",$I9="Yes — UK Critical SKU"),"Urgent — UK Launch Impact",IF($G9="High Risk","High",IF($G9="Medium Risk","Medium","Low"))) -> Urgent — UK Launch Impact
A10: ='Purchase Orders'!A10 -> PO-414 | B10: ='Purchase Orders'!B10 -> Factory E | C10: ='Purchase Orders'!D10 -> HN-EO-030 | D10: ='Purchase Orders'!E10 -> Essential Oil Blend 30ml | E10: ='Purchase Orders'!F10 -> 200 | F10: ='Purchase Orders'!G10 -> Unconfirmed — awaiting factory response (4 days) | G10: ='Purchase Orders'!O10 -> High Risk | H10: ='Purchase Orders'!H10 -> Unknown | I10: =IF(IFERROR(INDEX('Inventory & Coverage'!$M$8:$M$16,MATCH($C10,'Inventory & Coverage'!$A$8:$A$16,0)),"")="High Risk","Yes — UK Critical SKU","No") -> Yes — UK Critical SKU | J10: =IF($G10="Low Risk","No","Yes") -> Yes | K10: =IF(ISNUMBER(SEARCH("delayed",$F10)),"Contact factory for a revised production timeline. If this is a UK-critical SKU, evaluate air freight or a backup factory to recover schedule.",IF(ISNUMBER(SEARCH("Unconfirmed",$F10)),"Escalate to factory immediately — no confirmation received. Confirm the production slot or reallocate the PO to a backup factory.",IF(ISNUMBER(SEARCH("Completed",$F10)),"Issue shipping instructions now. Goods are finished and awaiting dispatch — assign a destination and carrier immediately to avoid storage delays.",IF(ISNUMBER(SEARCH("on track",$F10)),"No follow-up needed — monitor for on-time delivery.","Review PO status manually.")))) -> Escalate to factory immediately — no confirmation received. Confirm the production slot or reallocate the PO to a backup factory. | L10: =IF(AND($G10<>"Low Risk",$I10="Yes — UK Critical SKU"),"Urgent — UK Launch Impact",IF($G10="High Risk","High",IF($G10="Medium Risk","Medium","Low"))) -> Urgent — UK Launch Impact
A11: ='Purchase Orders'!A11 -> PO-415 | B11: ='Purchase Orders'!B11 -> Factory F | C11: ='Purchase Orders'!D11 -> HN-BC-400 | D11: ='Purchase Orders'!E11 -> Bath Crystals 400g | E11: ='Purchase Orders'!F11 -> 500 | F11: ='Purchase Orders'!G11 -> In production — on track | G11: ='Purchase Orders'!O11 -> Low Risk | H11: ='Purchase Orders'!H11 -> US | I11: =IF(IFERROR(INDEX('Inventory & Coverage'!$M$8:$M$16,MATCH($C11,'Inventory & Coverage'!$A$8:$A$16,0)),"")="High Risk","Yes — UK Critical SKU","No") -> Yes — UK Critical SKU | J11: =IF($G11="Low Risk","No","Yes") -> No | K11: =IF(ISNUMBER(SEARCH("delayed",$F11)),"Contact factory for a revised production timeline. If this is a UK-critical SKU, evaluate air freight or a backup factory to recover schedule.",IF(ISNUMBER(SEARCH("Unconfirmed",$F11)),"Escalate to factory immediately — no confirmation received. Confirm the production slot or reallocate the PO to a backup factory.",IF(ISNUMBER(SEARCH("Completed",$F11)),"Issue shipping instructions now. Goods are finished and awaiting dispatch — assign a destination and carrier immediately to avoid storage delays.",IF(ISNUMBER(SEARCH("on track",$F11)),"No follow-up needed — monitor for on-time delivery.","Review PO status manually.")))) -> No follow-up needed — monitor for on-time delivery. | L11: =IF(AND($G11<>"Low Risk",$I11="Yes — UK Critical SKU"),"Urgent — UK Launch Impact",IF($G11="High Risk","High",IF($G11="Medium Risk","Medium","Low"))) -> Low
A13: Notes & Assumptions
A14: • Every PO is listed (not just flagged ones) so the sheet reflects the full open-PO picture; use the Follow-Up Needed and Priority columns to triage.
A15: • Affects UK Restock? flags Yes when the PO's SKU currently shows High UK stockout risk on Inventory & Coverage — i.e. this factory's output matters for the UK launch even though the PO itself may not ship to UK.
A16: • Priority is 'Urgent — UK Launch Impact' when a non-Low-Risk PO involves a UK-critical SKU, since resolving it protects the UK launch specifically.
A17: • Recommended Action is derived from keywords in the Status text and recalculates automatically if a PO's status is updated.

Sheet Purchase Orders
A1: Purchase Orders
A3: Blue text = source input data entered from PO records. Black text = formulas (do not overwrite).
A5: PO # | B5: Factory | C5: Factory City | D5: SKU | E5: Product | F5: Qty | G5: Status | H5: Destination Warehouse | I5: Ship Method | J5: Stated ETA Notes | K5: Stated ETA (Weeks) | L5: Ref. Sea Transit (Wks) | M5: Ref. Air Transit (Wks) | N5: Applicable Ref. Transit (Wks) | O5: PO Risk Flag | P5: Ships to UK Warehouse?
A6: PO-410 | B6: Factory A | C6: =IFERROR(INDEX('Reference Data'!$B$22:$B$27,MATCH(B6,'Reference Data'!$A$22:$A$27,0)),"N/A") -> Shenzhen | D6: HN-RB-300 | E6: =IFERROR(INDEX('Reference Data'!$B$10:$B$18,MATCH(D6,'Reference Data'!$A$10:$A$18,0)),"N/A") -> Recovery Balm 300ml | F6: 500 | G6: In production — on track | H6: HK | I6: Sea | J6: Ships to HK, ETA 3.5 weeks | K6: 3.5 | L6: =IFERROR(INDEX('Reference Data'!$C$31:$C$45,MATCH($C6&"|"&$H6,'Reference Data'!$F$31:$F$45,0)),"N/A") -> 0.28571429 | M6: =IFERROR(INDEX('Reference Data'!$E$31:$E$45,MATCH($C6&"|"&$H6,'Reference Data'!$F$31:$F$45,0)),"N/A") -> 0.14285714 | N6: =IF(I6="Air",M6,IF(I6="Sea",L6,"N/A")) -> 0.28571429 | O6: =IF(ISNUMBER(SEARCH("delayed",G6)),"High Risk",IF(ISNUMBER(SEARCH("Unconfirmed",G6)),"High Risk",IF(ISNUMBER(SEARCH("Completed",G6)),"Medium Risk",IF(ISNUMBER(SEARCH("on track",G6)),"Low Risk","Review")))) -> Low Risk | P6: =IF(H6="UK","Yes","No") -> No
A7: PO-411 | B7: Factory A | C7: =IFERROR(INDEX('Reference Data'!$B$22:$B$27,MATCH(B7,'Reference Data'!$A$22:$A$27,0)),"N/A") -> Shenzhen | D7: HN-NC-075 | E7: =IFERROR(INDEX('Reference Data'!$B$10:$B$18,MATCH(D7,'Reference Data'!$A$10:$A$18,0)),"N/A") -> Night Cream 75ml | F7: 500 | G7: In production — on track | H7: US | I7: Sea | J7: Ships to LA, ETA 4 weeks | K7: 4 | L7: =IFERROR(INDEX('Reference Data'!$C$31:$C$45,MATCH($C7&"|"&$H7,'Reference Data'!$F$31:$F$45,0)),"N/A") -> 3 | M7: =IFERROR(INDEX('Reference Data'!$E$31:$E$45,MATCH($C7&"|"&$H7,'Reference Data'!$F$31:$F$45,0)),"N/A") -> 0.71428571 | N7: =IF(I7="Air",M7,IF(I7="Sea",L7,"N/A")) -> 3 | O7: =IF(ISNUMBER(SEARCH("delayed",G7)),"High Risk",IF(ISNUMBER(SEARCH("Unconfirmed",G7)),"High Risk",IF(ISNUMBER(SEARCH("Completed",G7)),"Medium Risk",IF(ISNUMBER(SEARCH("on track",G7)),"Low Risk","Review")))) -> Low Risk | P7: =IF(H7="UK","Yes","No") -> No
A8: PO-412 | B8: Factory C | C8: =IFERROR(INDEX('Reference Data'!$B$22:$B$27,MATCH(B8,'Reference Data'!$A$22:$A$27,0)),"N/A") -> Jakarta | D8: HN-HM-100 | E8: =IFERROR(INDEX('Reference Data'!$B$10:$B$18,MATCH(D8,'Reference Data'!$A$10:$A$18,0)),"N/A") -> Hair Mask 100ml | F8: 300 | G8: Production delayed — raw material shortage | H8: Unknown | I8: Unknown | J8: Originally ETA 3 weeks, now unknown | K8: Unknown | L8: =IFERROR(INDEX('Reference Data'!$C$31:$C$45,MATCH($C8&"|"&$H8,'Reference Data'!$F$31:$F$45,0)),"N/A") -> N/A | M8: =IFERROR(INDEX('Reference Data'!$E$31:$E$45,MATCH($C8&"|"&$H8,'Reference Data'!$F$31:$F$45,0)),"N/A") -> N/A | N8: =IF(I8="Air",M8,IF(I8="Sea",L8,"N/A")) -> N/A | O8: =IF(ISNUMBER(SEARCH("delayed",G8)),"High Risk",IF(ISNUMBER(SEARCH("Unconfirmed",G8)),"High Risk",IF(ISNUMBER(SEARCH("Completed",G8)),"Medium Risk",IF(ISNUMBER(SEARCH("on track",G8)),"Low Risk","Review")))) -> High Risk | P8: =IF(H8="UK","Yes","No") -> No
A9: PO-413 | B9: Factory D | C9: =IFERROR(INDEX('Reference Data'!$B$22:$B$27,MATCH(B9,'Reference Data'!$A$22:$A$27,0)),"N/A") -> Taipei | D9: HN-LB-250 | E9: =IFERROR(INDEX('Reference Data'!$B$10:$B$18,MATCH(D9,'Reference Data'!$A$10:$A$18,0)),"N/A") -> Lip Balm 3-Pack | F9: 1000 | G9: Completed — ready for pickup | H9: Unknown | I9: Unknown | J9: Awaiting shipping instructions | K9: Unknown | L9: =IFERROR(INDEX('Reference Data'!$C$31:$C$45,MATCH($C9&"|"&$H9,'Reference Data'!$F$31:$F$45,0)),"N/A") -> N/A | M9: =IFERROR(INDEX('Reference Data'!$E$31:$E$45,MATCH($C9&"|"&$H9,'Reference Data'!$F$31:$F$45,0)),"N/A") -> N/A | N9: =IF(I9="Air",M9,IF(I9="Sea",L9,"N/A")) -> N/A | O9: =IF(ISNUMBER(SEARCH("delayed",G9)),"High Risk",IF(ISNUMBER(SEARCH("Unconfirmed",G9)),"High Risk",IF(ISNUMBER(SEARCH("Completed",G9)),"Medium Risk",IF(ISNUMBER(SEARCH("on track",G9)),"Low Risk","Review")))) -> Medium Risk | P9: =IF(H9="UK","Yes","No") -> No
A10: PO-414 | B10: Factory E | C10: =IFERROR(INDEX('Reference Data'!$B$22:$B$27,MATCH(B10,'Reference Data'!$A$22:$A$27,0)),"N/A") -> Chiang Mai | D10: HN-EO-030 | E10: =IFERROR(INDEX('Reference Data'!$B$10:$B$18,MATCH(D10,'Reference Data'!$A$10:$A$18,0)),"N/A") -> Essential Oil Blend 30ml | F10: 200 | G10: Unconfirmed — awaiting factory response (4 days) | H10: Unknown | I10: Unknown | J10: Unknown | K10: Unknown | L10: =IFERROR(INDEX('Reference Data'!$C$31:$C$45,MATCH($C10&"|"&$H10,'Reference Data'!$F$31:$F$45,0)),"N/A") -> N/A | M10: =IFERROR(INDEX('Reference Data'!$E$31:$E$45,MATCH($C10&"|"&$H10,'Reference Data'!$F$31:$F$45,0)),"N/A") -> N/A | N10: =IF(I10="Air",M10,IF(I10="Sea",L10,"N/A")) -> N/A | O10: =IF(ISNUMBER(SEARCH("delayed",G10)),"High Risk",IF(ISNUMBER(SEARCH("Unconfirmed",G10)),"High Risk",IF(ISNUMBER(SEARCH("Completed",G10)),"Medium Risk",IF(ISNUMBER(SEARCH("on track",G10)),"Low Risk","Review")))) -> High Risk | P10: =IF(H10="UK","Yes","No") -> No
A11: PO-415 | B11: Factory F | C11: =IFERROR(INDEX('Reference Data'!$B$22:$B$27,MATCH(B11,'Reference Data'!$A$22:$A$27,0)),"N/A") -> Ho Chi Minh City | D11: HN-BC-400 | E11: =IFERROR(INDEX('Reference Data'!$B$10:$B$18,MATCH(D11,'Reference Data'!$A$10:$A$18,0)),"N/A") -> Bath Crystals 400g | F11: 500 | G11: In production — on track | H11: US | I11: Sea | J11: Ships to LA, ETA 6 weeks (sea) | K11: 6 | L11: =IFERROR(INDEX('Reference Data'!$C$31:$C$45,MATCH($C11&"|"&$H11,'Reference Data'!$F$31:$F$45,0)),"N/A") -> 3.5 | M11: =IFERROR(INDEX('Reference Data'!$E$31:$E$45,MATCH($C11&"|"&$H11,'Reference Data'!$F$31:$F$45,0)),"N/A") -> 0.71428571 | N11: =IF(I11="Air",M11,IF(I11="Sea",L11,"N/A")) -> 3.5 | O11: =IF(ISNUMBER(SEARCH("delayed",G11)),"High Risk",IF(ISNUMBER(SEARCH("Unconfirmed",G11)),"High Risk",IF(ISNUMBER(SEARCH("Completed",G11)),"Medium Risk",IF(ISNUMBER(SEARCH("on track",G11)),"Low Risk","Review")))) -> Low Risk | P11: =IF(H11="UK","Yes","No") -> No
A12: TOTAL | F12: =SUM(F6:F11) -> 3000
A14: Notes & Assumptions
A15: • Destination Warehouse and Ship Method are extracted from each PO's status/ETA notes as provided; recorded as 'Unknown' where the source did not specify a destination or method yet.
A16: • Ship Method is assumed 'Sea' where not explicitly stated but the ETA is multi-week in scale (consistent with sea freight lead times in Reference Data); PO-415 explicitly stated '(sea)'.
A17: • PO Risk Flag is a formula that searches the Status text for keywords ("delayed", "Unconfirmed", "Completed", "on track") — edit the Status text and the flag recalculates automatically.
A18: • Reference Sea/Air Transit columns are pulled live from the Reference Data Shipping Lead Times table via the Factory City + Destination Warehouse route — they show the typical transit time for that lane, for comparison against the Stated ETA.

Sheet Inventory & Coverage
A1: Inventory & Coverage
A3: Stockout Risk Thresholds (editable assumptions):
A4: High Risk if Weeks of Cover < | B4: 4
A5: Medium Risk if Weeks of Cover < | B5: 8 | C5: (Low Risk otherwise)
A7: SKU | B7: Product | C7: Category | D7: Primary Factory | E7: US (LA) Qty | F7: UK (Manchester) Qty | G7: HK Qty | H7: Total Qty | I7: Weekly Sell- Through Rate | J7: Total Weeks of Cover | K7: Total Stockout Risk | L7: UK Weeks of Cover | M7: UK Stockout Risk | N7: Open PO Qty (All Dest.) | O7: Open PO Qty to UK
A8: HN-RB-300 | B8: =IFERROR(INDEX('Reference Data'!$B$10:$B$18,MATCH($A8,'Reference Data'!$A$10:$A$18,0)),"N/A") -> Recovery Balm 300ml | C8: =IFERROR(INDEX('Reference Data'!$C$10:$C$18,MATCH($A8,'Reference Data'!$A$10:$A$18,0)),"N/A") -> Body Care | D8: =IFERROR(INDEX('Reference Data'!$D$10:$D$18,MATCH($A8,'Reference Data'!$A$10:$A$18,0)),"N/A") -> Factory A | E8: 220 | F8: 35 | G8: 110 | H8: =SUM(E8:G8) -> 365 | I8: 75 | J8: =IFERROR(H8/I8,"N/A") -> 4.8666667 | K8: =IF(J8<$B$4,"High Risk",IF(J8<$B$5,"Medium Risk","Low Risk")) -> Medium Risk | L8: =IFERROR(F8/I8,"N/A") -> 0.46666667 | M8: =IF(L8<$B$4,"High Risk",IF(L8<$B$5,"Medium Risk","Low Risk")) -> High Risk | N8: =SUMIF('Purchase Orders'!$D$6:$D$11,$A8,'Purchase Orders'!$F$6:$F$11) -> 500 | O8: =SUMIFS('Purchase Orders'!$F$6:$F$11,'Purchase Orders'!$D$6:$D$11,$A8,'Purchase Orders'!$H$6:$H$11,"UK") -> 0
A9: HN-FS-050 | B9: =IFERROR(INDEX('Reference Data'!$B$10:$B$18,MATCH($A9,'Reference Data'!$A$10:$A$18,0)),"N/A") -> Face Serum 50ml | C9: =IFERROR(INDEX('Reference Data'!$C$10:$C$18,MATCH($A9,'Reference Data'!$A$10:$A$18,0)),"N/A") -> Skincare | D9: =IFERROR(INDEX('Reference Data'!$D$10:$D$18,MATCH($A9,'Reference Data'!$A$10:$A$18,0)),"N/A") -> Factory A | E9: 150 | F9: 20 | G9: 75 | H9: =SUM(E9:G9) -> 245 | I9: 45 | J9: =IFERROR(H9/I9,"N/A") -> 5.4444444 | K9: =IF(J9<$B$4,"High Risk",IF(J9<$B$5,"Medium Risk","Low Risk")) -> Medium Risk | L9: =IFERROR(F9/I9,"N/A") -> 0.44444444 | M9: =IF(L9<$B$4,"High Risk",IF(L9<$B$5,"Medium Risk","Low Risk")) -> High Risk | N9: =SUMIF('Purchase Orders'!$D$6:$D$11,$A9,'Purchase Orders'!$F$6:$F$11) -> 0 | O9: =SUMIFS('Purchase Orders'!$F$6:$F$11,'Purchase Orders'!$D$6:$D$11,$A9,'Purchase Orders'!$H$6:$H$11,"UK") -> 0
A10: HN-BW-200 | B10: =IFERROR(INDEX('Reference Data'!$B$10:$B$18,MATCH($A10,'Reference Data'!$A$10:$A$18,0)),"N/A") -> Body Wash 200ml | C10: =IFERROR(INDEX('Reference Data'!$C$10:$C$18,MATCH($A10,'Reference Data'!$A$10:$A$18,0)),"N/A") -> Body Care | D10: =IFERROR(INDEX('Reference Data'!$D$10:$D$18,MATCH($A10,'Reference Data'!$A$10:$A$18,0)),"N/A") -> Factory B | E10: 180 | F10: 50 | G10: 60 | H10: =SUM(E10:G10) -> 290 | I10: 55 | J10: =IFERROR(H10/I10,"N/A") -> 5.2727273 | K10: =IF(J10<$B$4,"High Risk",IF(J10<$B$5,"Medium Risk","Low Risk")) -> Medium Risk | L10: =IFERROR(F10/I10,"N/A") -> 0.90909091 | M10: =IF(L10<$B$4,"High Risk",IF(L10<$B$5,"Medium Risk","Low Risk")) -> High Risk | N10: =SUMIF('Purchase Orders'!$D$6:$D$11,$A10,'Purchase Orders'!$F$6:$F$11) -> 0 | O10: =SUMIFS('Purchase Orders'!$F$6:$F$11,'Purchase Orders'!$D$6:$D$11,$A10,'Purchase Orders'!$H$6:$H$11,"UK") -> 0
A11: HN-HM-100 | B11: =IFERROR(INDEX('Reference Data'!$B$10:$B$18,MATCH($A11,'Reference Data'!$A$10:$A$18,0)),"N/A") -> Hair Mask 100ml | C11: =IFERROR(INDEX('Reference Data'!$C$10:$C$18,MATCH($A11,'Reference Data'!$A$10:$A$18,0)),"N/A") -> Hair Care | D11: =IFERROR(INDEX('Reference Data'!$D$10:$D$18,MATCH($A11,'Reference Data'!$A$10:$A$18,0)),"N/A") -> Factory C | E11: 90 | F11: 25 | G11: 45 | H11: =SUM(E11:G11) -> 160 | I11: 30 | J11: =IFERROR(H11/I11,"N/A") -> 5.3333333 | K11: =IF(J11<$B$4,"High Risk",IF(J11<$B$5,"Medium Risk","Low Risk")) -> Medium Risk | L11: =IFERROR(F11/I11,"N/A") -> 0.83333333 | M11: =IF(L11<$B$4,"High Risk",IF(L11<$B$5,"Medium Risk","Low Risk")) -> High Risk | N11: =SUMIF('Purchase Orders'!$D$6:$D$11,$A11,'Purchase Orders'!$F$6:$F$11) -> 300 | O11: =SUMIFS('Purchase Orders'!$F$6:$F$11,'Purchase Orders'!$D$6:$D$11,$A11,'Purchase Orders'!$H$6:$H$11,"UK") -> 0
A12: HN-LB-250 | B12: =IFERROR(INDEX('Reference Data'!$B$10:$B$18,MATCH($A12,'Reference Data'!$A$10:$A$18,0)),"N/A") -> Lip Balm 3-Pack | C12: =IFERROR(INDEX('Reference Data'!$C$10:$C$18,MATCH($A12,'Reference Data'!$A$10:$A$18,0)),"N/A") -> Skincare | D12: =IFERROR(INDEX('Reference Data'!$D$10:$D$18,MATCH($A12,'Reference Data'!$A$10:$A$18,0)),"N/A") -> Factory D | E12: 300 | F12: 40 | G12: 80 | H12: =SUM(E12:G12) -> 420 | I12: 60 | J12: =IFERROR(H12/I12,"N/A") -> 7 | K12: =IF(J12<$B$4,"High Risk",IF(J12<$B$5,"Medium Risk","Low Risk")) -> Medium Risk | L12: =IFERROR(F12/I12,"N/A") -> 0.66666667 | M12: =IF(L12<$B$4,"High Risk",IF(L12<$B$5,"Medium Risk","Low Risk")) -> High Risk | N12: =SUMIF('Purchase Orders'!$D$6:$D$11,$A12,'Purchase Orders'!$F$6:$F$11) -> 1000 | O12: =SUMIFS('Purchase Orders'!$F$6:$F$11,'Purchase Orders'!$D$6:$D$11,$A12,'Purchase Orders'!$H$6:$H$11,"UK") -> 0
A13: HN-SM-150 | B13: =IFERROR(INDEX('Reference Data'!$B$10:$B$18,MATCH($A13,'Reference Data'!$A$10:$A$18,0)),"N/A") -> Scalp Mist 150ml | C13: =IFERROR(INDEX('Reference Data'!$C$10:$C$18,MATCH($A13,'Reference Data'!$A$10:$A$18,0)),"N/A") -> Hair Care | D13: =IFERROR(INDEX('Reference Data'!$D$10:$D$18,MATCH($A13,'Reference Data'!$A$10:$A$18,0)),"N/A") -> Factory C | E13: 70 | F13: 10 | G13: 30 | H13: =SUM(E13:G13) -> 110 | I13: 20 | J13: =IFERROR(H13/I13,"N/A") -> 5.5 | K13: =IF(J13<$B$4,"High Risk",IF(J13<$B$5,"Medium Risk","Low Risk")) -> Medium Risk | L13: =IFERROR(F13/I13,"N/A") -> 0.5 | M13: =IF(L13<$B$4,"High Risk",IF(L13<$B$5,"Medium Risk","Low Risk")) -> High Risk | N13: =SUMIF('Purchase Orders'!$D$6:$D$11,$A13,'Purchase Orders'!$F$6:$F$11) -> 0 | O13: =SUMIFS('Purchase Orders'!$F$6:$F$11,'Purchase Orders'!$D$6:$D$11,$A13,'Purchase Orders'!$H$6:$H$11,"UK") -> 0
A14: HN-EO-030 | B14: =IFERROR(INDEX('Reference Data'!$B$10:$B$18,MATCH($A14,'Reference Data'!$A$10:$A$18,0)),"N/A") -> Essential Oil Blend 30ml | C14: =IFERROR(INDEX('Reference Data'!$C$10:$C$18,MATCH($A14,'Reference Data'!$A$10:$A$18,0)),"N/A") -> Wellness | D14: =IFERROR(INDEX('Reference Data'!$D$10:$D$18,MATCH($A14,'Reference Data'!$A$10:$A$18,0)),"N/A") -> Factory E | E14: 45 | F14: 8 | G14: 20 | H14: =SUM(E14:G14) -> 73 | I14: 15 | J14: =IFERROR(H14/I14,"N/A") -> 4.8666667 | K14: =IF(J14<$B$4,"High Risk",IF(J14<$B$5,"Medium Risk","Low Risk")) -> Medium Risk | L14: =IFERROR(F14/I14,"N/A") -> 0.53333333 | M14: =IF(L14<$B$4,"High Risk",IF(L14<$B$5,"Medium Risk","Low Risk")) -> High Risk | N14: =SUMIF('Purchase Orders'!$D$6:$D$11,$A14,'Purchase Orders'!$F$6:$F$11) -> 200 | O14: =SUMIFS('Purchase Orders'!$F$6:$F$11,'Purchase Orders'!$D$6:$D$11,$A14,'Purchase Orders'!$H$6:$H$11,"UK") -> 0
A15: HN-BC-400 | B15: =IFERROR(INDEX('Reference Data'!$B$10:$B$18,MATCH($A15,'Reference Data'!$A$10:$A$18,0)),"N/A") -> Bath Crystals 400g | C15: =IFERROR(INDEX('Reference Data'!$C$10:$C$18,MATCH($A15,'Reference Data'!$A$10:$A$18,0)),"N/A") -> Body Care | D15: =IFERROR(INDEX('Reference Data'!$D$10:$D$18,MATCH($A15,'Reference Data'!$A$10:$A$18,0)),"N/A") -> Factory F | E15: 60 | F15: 15 | G15: 25 | H15: =SUM(E15:G15) -> 100 | I15: 25 | J15: =IFERROR(H15/I15,"N/A") -> 4 | K15: =IF(J15<$B$4,"High Risk",IF(J15<$B$5,"Medium Risk","Low Risk")) -> Medium Risk | L15: =IFERROR(F15/I15,"N/A") -> 0.6 | M15: =IF(L15<$B$4,"High Risk",IF(L15<$B$5,"Medium Risk","Low Risk")) -> High Risk | N15: =SUMIF('Purchase Orders'!$D$6:$D$11,$A15,'Purchase Orders'!$F$6:$F$11) -> 500 | O15: =SUMIFS('Purchase Orders'!$F$6:$F$11,'Purchase Orders'!$D$6:$D$11,$A15,'Purchase Orders'!$H$6:$H$11,"UK") -> 0
A16: HN-NC-075 | B16: =IFERROR(INDEX('Reference Data'!$B$10:$B$18,MATCH($A16,'Reference Data'!$A$10:$A$18,0)),"N/A") -> Night Cream 75ml | C16: =IFERROR(INDEX('Reference Data'!$C$10:$C$18,MATCH($A16,'Reference Data'!$A$10:$A$18,0)),"N/A") -> Skincare | D16: =IFERROR(INDEX('Reference Data'!$D$10:$D$18,MATCH($A16,'Reference Data'!$A$10:$A$18,0)),"N/A") -> Factory A | E16: 130 | F16: 18 | G16: 55 | H16: =SUM(E16:G16) -> 203 | I16: 40 | J16: =IFERROR(H16/I16,"N/A") -> 5.075 | K16: =IF(J16<$B$4,"High Risk",IF(J16<$B$5,"Medium Risk","Low Risk")) -> Medium Risk | L16: =IFERROR(F16/I16,"N/A") -> 0.45 | M16: =IF(L16<$B$4,"High Risk",IF(L16<$B$5,"Medium Risk","Low Risk")) -> High Risk | N16: =SUMIF('Purchase Orders'!$D$6:$D$11,$A16,'Purchase Orders'!$F$6:$F$11) -> 500 | O16: =SUMIFS('Purchase Orders'!$F$6:$F$11,'Purchase Orders'!$D$6:$D$11,$A16,'Purchase Orders'!$H$6:$H$11,"UK") -> 0
A17: TOTAL | E17: =SUM(E8:E16) -> 1245 | F17: =SUM(F8:F16) -> 221 | G17: =SUM(G8:G16) -> 500 | H17: =SUM(H8:H16) -> 1966 | N17: =SUM(N8:N16) -> 3000 | O17: =SUM(O8:O16) -> 0
A19: Notes & Assumptions
A20: • Product, Category, and Primary Factory are looked up live from the Reference Data Product Catalog — SKU is the only identifying input needed on this sheet.
A21: • Weekly Sell-Through Rate is a single blended rate per SKU (not broken out by warehouse), as provided in source data. UK Weeks of Cover therefore approximates the UK warehouse independently covering total demand at that SKU's overall sell-through rate — read it as a directional risk indicator, not a precise per-location forecast.
A22: • Open PO Qty columns pull live from the Purchase Orders sheet (SUMIF/SUMIFS by SKU), so incoming replenishment updates automatically as POs change.
A23: • Risk thresholds in B4:B5 are editable assumptions — changing them recalculates every Stockout Risk flag on this sheet.

Sheet Reference Data
A1: Reference Data
A3: Fulfillment Warehouses
A4: Warehouse Code | B4: Region / Name | C4: City
A5: US | B5: US West | C5: Los Angeles
A6: UK | B6: UK | C6: Manchester
A7: HK | B7: Asia | C7: Hong Kong
A8: Product Catalog
A9: SKU | B9: Product | C9: Category | D9: Primary Factory
A10: HN-RB-300 | B10: Recovery Balm 300ml | C10: Body Care | D10: Factory A
A11: HN-FS-050 | B11: Face Serum 50ml | C11: Skincare | D11: Factory A
A12: HN-BW-200 | B12: Body Wash 200ml | C12: Body Care | D12: Factory B
A13: HN-HM-100 | B13: Hair Mask 100ml | C13: Hair Care | D13: Factory C
A14: HN-LB-250 | B14: Lip Balm 3-Pack | C14: Skincare | D14: Factory D
A15: HN-SM-150 | B15: Scalp Mist 150ml | C15: Hair Care | D15: Factory C
A16: HN-EO-030 | B16: Essential Oil Blend 30ml | C16: Wellness | D16: Factory E
A17: HN-BC-400 | B17: Bath Crystals 400g | C17: Body Care | D17: Factory F
A18: HN-NC-075 | B18: Night Cream 75ml | C18: Skincare | D18: Factory A
A20: Factory Network
A21: Factory | B21: City | C21: Country | D21: SKUs Produced | E21: MOQ | F21: MOQ (Units, Numeric) | G21: Production Lead Time (Weeks) | H21: Status
A22: Factory A | B22: Shenzhen | C22: China | D22: HN-RB-300, HN-FS-050, HN-NC-075 | E22: 500 units/SKU | F22: 500 | G22: 3 | H22: Active — reliable, primary partner
A23: Factory B | B23: Chiang Mai | C23: Thailand | D23: HN-BW-200 | E23: 400 units | F23: 400 | G23: 2.5 | H23: Active — reliable
A24: Factory C | B24: Jakarta | C24: Indonesia | D24: HN-HM-100, HN-SM-150 | E24: 300 units/SKU | F24: 300 | G24: 3 | H24: Active — occasional delays
A25: Factory D | B25: Taipei | C25: Taiwan | D25: HN-LB-250 | E25: 1,000 units | F25: 1000 | G25: 2 | H25: Active — high MOQ but fast
A26: Factory E | B26: Chiang Mai | C26: Thailand | D26: HN-EO-030 | E26: 200 units | F26: 200 | G26: 2 | H26: New — first PO in progress
A27: Factory F | B27: Ho Chi Minh City | C27: Vietnam | D27: HN-BC-400 | E27: 500 units | F27: 500 | G27: 4 | H27: Active — long lead time
A29: Shipping Lead Times
A30: Origin (Factory City) | B30: Destination (Warehouse Code) | C30: Sea Freight (Weeks) | D30: Air Freight (Days) | E30: Air Freight (Weeks) | F30: Route Key
A31: Shenzhen | B31: US | C31: 3 | D31: 5 | E31: =D31/7 -> 0.71428571 | F31: =A31&"|"&B31 -> Shenzhen|US
A32: Shenzhen | B32: UK | C32: 5 | D32: 7 | E32: =D32/7 -> 1 | F32: =A32&"|"&B32 -> Shenzhen|UK
A33: Shenzhen | B33: HK | C33: 0.28571429 | D33: 1 | E33: =D33/7 -> 0.14285714 | F33: =A33&"|"&B33 -> Shenzhen|HK
A34: Chiang Mai | B34: US | C34: 4.5 | D34: 6 | E34: =D34/7 -> 0.85714286 | F34: =A34&"|"&B34 -> Chiang Mai|US
A35: Chiang Mai | B35: UK | C35: 4.5 | D35: 7 | E35: =D35/7 -> 1 | F35: =A35&"|"&B35 -> Chiang Mai|UK
A36: Chiang Mai | B36: HK | C36: 4 | D36: 2 | E36: =D36/7 -> 0.28571429 | F36: =A36&"|"&B36 -> Chiang Mai|HK
A37: Jakarta | B37: US | C37: 4 | D37: 6 | E37: =D37/7 -> 0.85714286 | F37: =A37&"|"&B37 -> Jakarta|US
A38: Jakarta | B38: UK | C38: 5 | D38: 7 | E38: =D38/7 -> 1 | F38: =A38&"|"&B38 -> Jakarta|UK
A39: Jakarta | B39: HK | C39: 4 | D39: 2 | E39: =D39/7 -> 0.28571429 | F39: =A39&"|"&B39 -> Jakarta|HK
A40: Taipei | B40: US | C40: 3 | D40: 4 | E40: =D40/7 -> 0.57142857 | F40: =A40&"|"&B40 -> Taipei|US
A41: Taipei | B41: UK | C41: 5 | D41: 6 | E41: =D41/7 -> 0.85714286 | F41: =A41&"|"&B41 -> Taipei|UK
A42: Taipei | B42: HK | C42: 0.28571429 | D42: 1 | E42: =D42/7 -> 0.14285714 | F42: =A42&"|"&B42 -> Taipei|HK
... A45: Ho Chi Minh City | B45: HK | C45: 3 | D45: 1 | E45: =D45/7 -> 0.14285714 | F45: =A45&"|"&B45 -> Ho Chi Minh City|HK
...
